***Soru:*** name              Expected goals
home                        0.73
away                        3.00
compareCode                    2
statisticsType          positive
valueType                  event
homeValue                   0.73
awayValue                    3.0
renderType                     1
key                expectedGoals
period                       ALL
groupName         Match overview
match_id                12436927
homeTotal                    NaN
awayTotal                    NaN
Name: 1, dtype: object  bana bu bilgilerden çıkarak bir django modeli oluşturur musun

**Cevap:** Tabii Ahmet, bu verilerden yola çıkarak `ExpectedGoals` adında bir Django modeli oluşturabiliriz. Bu model, her maç için beklenen gol verilerini ve ilgili istatistikleri depolamak amacıyla kullanılacak. Veritabanı modelinde her sütunu uygun veri tipleriyle temsil edeceğiz.

Aşağıda bu veriye dayalı olarak oluşturulabilecek bir Django modeli örneğini bulabilirsin:

```python
from django.db import models

class ExpectedGoals(models.Model):
    match_id = models.PositiveIntegerField(verbose_name="Match ID")
    home = models.FloatField(verbose_name="Home Expected Goals")
    away = models.FloatField(verbose_name="Away Expected Goals")
    compare_code = models.PositiveSmallIntegerField(verbose_name="Compare Code")
    statistics_type = models.CharField(max_length=50, verbose_name="Statistics Type")
    value_type = models.CharField(max_length=50, verbose_name="Value Type")
    home_value = models.FloatField(verbose_name="Home Value")
    away_value = models.FloatField(verbose_name="Away Value")
    render_type = models.PositiveSmallIntegerField(verbose_name="Render Type")
    key = models.CharField(max_length=50, verbose_name="Key")
    period = models.CharField(max_length=20, verbose_name="Period")
    group_name = models.CharField(max_length=50, verbose_name="Group Name")
    home_total = models.FloatField(null=True, blank=True, verbose_name="Home Total")
    away_total = models.FloatField(null=True, blank=True, verbose_name="Away Total")

    class Meta:
        verbose_name = "Expected Goals"
        verbose_name_plural = "Expected Goals"

    def __str__(self):
        return f"Match {self.match_id} - Expected Goals: Home {self.home} vs Away {self.away}"
```

### Açıklama:
- **match_id**: Maç kimliğini tutan `PositiveIntegerField`.
- **home**: Ev sahibi takımın beklenen gol sayısını tutan `FloatField`.
- **away**: Deplasman takımının beklenen gol sayısını tutan `FloatField`.
- **compare_code**: Karşılaştırma kodunu tutan `PositiveSmallIntegerField`.
- **statistics_type**: İstatistik türünü tanımlayan `CharField`.
- **value_type**: Değer türünü tanımlayan `CharField`.
- **home_value**: Ev sahibi takımın değerini tutan `FloatField`.
- **away_value**: Deplasman takımının değerini tutan `FloatField`.
- **render_type**: Görüntüleme türünü tutan `PositiveSmallIntegerField`.
- **key**: Anahtar bilgiyi tutan `CharField`.
- **period**: İlgili periyodu belirten `CharField`.
- **group_name**: Grup adını tutan `CharField`.
- **home_total** ve **away_total**: Toplam değerler için `FloatField`, opsiyonel olarak `null=True` ve `blank=True` olarak ayarlandı.

Bu modeli `models.py` dosyana ekleyip gerekli migrate işlemlerini yaptıktan sonra kullanabilirsin. Bu model, belirttiğin verileri veritabanında düzenli ve anlamlı bir yapıda saklamana yardımcı olacaktır.

***Soru:*** from django.db import models # type: ignore

class ExpectedGoals(models.Model):
    match_id = models.PositiveIntegerField(verbose_name="Match ID")
    home = models.FloatField(verbose_name="Home Expected Goals")
    away = models.FloatField(verbose_name="Away Expected Goals")
    compare_code = models.PositiveSmallIntegerField(verbose_name="Compare Code")
    statistics_type = models.CharField(max_length=50, verbose_name="Statistics Type")
    value_type = models.CharField(max_length=50, verbose_name="Value Type")
    home_value = models.FloatField(verbose_name="Home Value")
    away_value = models.FloatField(verbose_name="Away Value")
    render_type = models.PositiveSmallIntegerField(verbose_name="Render Type")
    key = models.CharField(max_length=50, verbose_name="Key")
    period = models.CharField(max_length=20, verbose_name="Period")
    group_name = models.CharField(max_length=50, verbose_name="Group Name")
    home_total = models.FloatField(null=True, blank=True, verbose_name="Home Total")
    away_total = models.FloatField(null=True, blank=True, verbose_name="Away Total")

    class Meta:
        verbose_name = "Expected Goals"
        verbose_name_plural = "Expected Goals"

    def __str__(self):
        return f"Match {self.match_id} - Expected Goals: Home {self.home} vs Away {self.away}"   şimdi bu modeli admine ekler misni

**Cevap:** Tabii, bu modeli admin paneline eklemek için `admin.py` dosyasına gerekli kodları ekleyeceğiz. `ExpectedGoals` modelini admin panelinde düzenleyebilir, görüntüleyebilir ve yönetebilirsin. Aşağıdaki adımları takip ederek modeli admin paneline ekleyebilirsin:

1. **`admin.py` Dosyasını Düzenle:**
   Proje yapında `expected_goals` adlı bir uygulama olduğunu varsayarsak, `admin.py` dosyasını aç ve aşağıdaki kodları ekle:

```python
from django.contrib import admin
from .models import ExpectedGoals

# ExpectedGoals modelini admin paneline ekleme
@admin.register(ExpectedGoals)
class ExpectedGoalsAdmin(admin.ModelAdmin):
    list_display = ('match_id', 'home', 'away', 'statistics_type', 'value_type', 'period', 'group_name')
    search_fields = ('match_id', 'key', 'group_name')
    list_filter = ('statistics_type', 'period', 'group_name')
    ordering = ('-match_id',)
```

2. **Açıklama:**
   - `list_display`: Admin panelinde görüntülemek istediğin sütunları belirtir.
   - `search_fields`: Belirtilen alanlara göre arama yapabilmeni sağlar.
   - `list_filter`: Filtreleme için kullanacağın sütunları belirtir.
   - `ordering`: Admin panelinde hangi sıraya göre sıralama yapacağını belirtir. `-match_id` ile `match_id`'ye göre azalan sırada sıralama yapılır.

3. **Admin Paneline Giriş:**
   Bu değişiklikleri yaptıktan sonra admin paneline giriş yaparak `ExpectedGoals` modelini görüntüleyebilirsin. Modeli görmüyorsan, aşağıdaki adımları kontrol et:

   - `expected_goals` uygulamasının `INSTALLED_APPS` içinde yer aldığından emin ol.
   - `python manage.py makemigrations` ve `python manage.py migrate` komutlarını çalıştırarak veritabanı şemasını güncelle.

Bu adımları takip ederek `ExpectedGoals` modelini admin paneline başarıyla ekleyebilir ve yönetebilirsin.

***Soru:*** rom django.db import models

class Match(models.Model):
    # Temel Bilgiler
    Tarih = models.DateField()  # Tarih için DateField kullanıyoruz
    customId = models.CharField(max_length=10)  # Unique olmasını istediğiniz için CharField seçildi
    id = models.BigIntegerField(primary_key=True,unique=True)  # Primary Key olarak belirttiniz
    startTimestamp = models.DateTimeField()  # Tarih ve saat bilgisi için DateTimeField kullanıldı
    
    # Turnuva Bilgileri
    tournament_name = models.CharField(max_length=255, blank=False, null=False)
    tournament_category_name = models.CharField(max_length=255, blank=False, null=False)
    season_name = models.CharField(max_length=50, blank=False, null=False)
    season_year = models.CharField(max_length=50, blank=False, null=False)
    tournament_uniqueTournament_id = models.IntegerField(blank=False, null=False)
    season_id = models.IntegerField(blank=False, null=False)
    roundInfo_round = models.IntegerField(blank=True, null=True, default=0)    
    # Maç Durumu
    status_type = models.CharField(max_length=50, blank=False, null=False)
    
    # Ev Sahibi Takım Bilgileri
    homeTeam_name = models.CharField(max_length=255, blank=False, null=False)
    homeTeam_nameCode = models.CharField(max_length=10, blank=False, null=False)
    homeTeam_id = models.IntegerField(blank=False, null=False)
    
    # Deplasman Takımı Bilgileri
    awayTeam_name = models.CharField(max_length=255, blank=False, null=False)
    awayTeam_nameCode = models.CharField(max_length=10, blank=False, null=False)
    awayTeam_id = models.IntegerField(blank=False, null=False)
    
    # Ev Sahibi Skor Bilgileri
    homeScore_normaltime = models.FloatField(default=0, blank=True, null=True)  # Varsayılan olarak 0 atanır ve boş değer kabul edilmez
    homeScore_period1 = models.FloatField(default=0, blank=True, null=True)
    homeScore_period2 = models.FloatField(default=0, blank=True, null=True)

    # Deplasman Skor Bilgileri
    awayScore_normaltime = models.FloatField(default=0, blank=True, null=True)
    awayScore_period1 = models.FloatField(default=0, blank=True, null=True)
    awayScore_period2 = models.FloatField(default=0, blank=True, null=True)


    class Meta:
        verbose_name = 'Maç'
        verbose_name_plural = 'Maçlar'

    def __str__(self):
        return f"{self.tournament_name} - {self.homeTeam_name} vs {self.awayTeam_name}"   şimdi bu modelden match id yi alacaksın ve ExpectedGoals  modeline ekleyeceksin import http.client
import json
import pandas as pd

def MacStats(match_id):


    conn = http.client.HTTPSConnection('www.sofascore.com')
    conn.request('GET', '/api/v1/event/'+str(match_id)+'/statistics')
    response = conn.getresponse()

    data = json.loads(response.read())["statistics"]
    all_data = pd.DataFrame()
  
    for period_data in data:
        period = period_data['period']
        for group in period_data['groups']:
            group_name = group['groupName']
            stats = group['statisticsItems']
            
            # Veriyi DataFrame'e çevir
            df = pd.json_normalize(stats)
            
            # Ekstra sütunlar ekle: period ve groupName
            df['period'] = period
            df['groupName'] = group_name
            
            # Sonuçları ana DataFrame'e ekle
            all_data = pd.concat([all_data, df], ignore_index=True)
            all_data["match_id"] = match_id
    
    return all_data
      

data = MacStats(12436927)
data  bu apiyiy kullanacaksın ve tasks.py ye ekleyecek şekilde yapacaksın artı hataları yönetmek için bir model yaz ve admine ekle bunu ben celery sgared task deocratörü ile ekle

**Cevap:** Bu senaryoda `ExpectedGoals` modelini `Match` modeline bağlayacağız ve API'den aldığımız verileri `ExpectedGoals` modeline kaydedeceğiz. Bunun için öncelikle `tasks.py` dosyasında bir Celery görevi oluşturacağız ve API'den veriyi çekip işleyeceğiz. Ayrıca hataları yönetmek için bir `MatchDataError` modeli oluşturacağız ve bu hataları admin paneline ekleyeceğiz.

### Adım 1: `ExpectedGoals` Modelini `Match` Modeline Bağlamak
`ExpectedGoals` modelini `Match` modeline `ForeignKey` ile bağlayacağız.

**models.py dosyasını güncelle:**

```python
from django.db import models

class Match(models.Model):
    # Temel Bilgiler
    Tarih = models.DateField()  
    customId = models.CharField(max_length=10)  
    id = models.BigIntegerField(primary_key=True, unique=True)  
    startTimestamp = models.DateTimeField()  
    
    # Turnuva Bilgileri
    tournament_name = models.CharField(max_length=255)
    tournament_category_name = models.CharField(max_length=255)
    season_name = models.CharField(max_length=50)
    season_year = models.CharField(max_length=50)
    tournament_uniqueTournament_id = models.IntegerField()
    season_id = models.IntegerField()
    roundInfo_round = models.IntegerField(blank=True, null=True, default=0)    
    # Maç Durumu
    status_type = models.CharField(max_length=50)
    
    # Ev Sahibi Takım Bilgileri
    homeTeam_name = models.CharField(max_length=255)
    homeTeam_nameCode = models.CharField(max_length=10)
    homeTeam_id = models.IntegerField()
    
    # Deplasman Takımı Bilgileri
    awayTeam_name = models.CharField(max_length=255)
    awayTeam_nameCode = models.CharField(max_length=10)
    awayTeam_id = models.IntegerField()
    
    # Ev Sahibi Skor Bilgileri
    homeScore_normaltime = models.FloatField(default=0, blank=True, null=True)  
    homeScore_period1 = models.FloatField(default=0, blank=True, null=True)
    homeScore_period2 = models.FloatField(default=0, blank=True, null=True)

    # Deplasman Skor Bilgileri
    awayScore_normaltime = models.FloatField(default=0, blank=True, null=True)
    awayScore_period1 = models.FloatField(default=0, blank=True, null=True)
    awayScore_period2 = models.FloatField(default=0, blank=True, null=True)

    class Meta:
        verbose_name = 'Maç'
        verbose_name_plural = 'Maçlar'

    def __str__(self):
        return f"{self.tournament_name} - {self.homeTeam_name} vs {self.awayTeam_name}"


class ExpectedGoals(models.Model):
    match = models.ForeignKey(Match, on_delete=models.CASCADE, related_name='expected_goals', verbose_name="Match")
    home = models.FloatField(verbose_name="Home Expected Goals")
    away = models.FloatField(verbose_name="Away Expected Goals")
    compare_code = models.PositiveSmallIntegerField(verbose_name="Compare Code")
    statistics_type = models.CharField(max_length=50, verbose_name="Statistics Type")
    value_type = models.CharField(max_length=50, verbose_name="Value Type")
    home_value = models.FloatField(verbose_name="Home Value")
    away_value = models.FloatField(verbose_name="Away Value")
    render_type = models.PositiveSmallIntegerField(verbose_name="Render Type")
    key = models.CharField(max_length=50, verbose_name="Key")
    period = models.CharField(max_length=20, verbose_name="Period")
    group_name = models.CharField(max_length=50, verbose_name="Group Name")
    home_total = models.FloatField(null=True, blank=True, verbose_name="Home Total")
    away_total = models.FloatField(null=True, blank=True, verbose_name="Away Total")

    class Meta:
        verbose_name = "Expected Goals"
        verbose_name_plural = "Expected Goals"

    def __str__(self):
        return f"Match {self.match.id} - Expected Goals: Home {self.home} vs Away {self.away}"


class MatchDataError(models.Model):
    match_id = models.IntegerField(verbose_name="Match ID")
    error_message = models.TextField(verbose_name="Error Message")
    timestamp = models.DateTimeField(auto_now_add=True, verbose_name="Timestamp")

    class Meta:
        verbose_name = "Match Data Error"
        verbose_name_plural = "Match Data Errors"

    def __str__(self):
        return f"Error for Match ID {self.match_id} at {self.timestamp}"
```

### Adım 2: `tasks.py` Dosyasını Oluşturma ve Celery Görevi Tanımlama

`tasks.py` dosyasını oluştur ve aşağıdaki kodları ekle:

```python
from celery import shared_task
from django.db import IntegrityError
from .models import Match, ExpectedGoals, MatchDataError
import http.client
import json
import pandas as pd

@shared_task
def fetch_match_statistics(match_id):
    try:
        # API'ye bağlanma ve veri çekme
        conn = http.client.HTTPSConnection('www.sofascore.com')
        conn.request('GET', f'/api/v1/event/{match_id}/statistics')
        response = conn.getresponse()

        if response.status != 200:
            raise ValueError(f"API request failed with status code {response.status}")

        data = json.loads(response.read())["statistics"]
        all_data = pd.DataFrame()

        for period_data in data:
            period = period_data['period']
            for group in period_data['groups']:
                group_name = group['groupName']
                stats = group['statisticsItems']

                # Veriyi DataFrame'e çevirme
                df = pd.json_normalize(stats)
                df['period'] = period
                df['groupName'] = group_name
                df['match_id'] = match_id
                all_data = pd.concat([all_data, df], ignore_index=True)

        # Maç bilgilerini veritabanında bulma
        match = Match.objects.get(id=match_id)

        # ExpectedGoals modeline veri ekleme
        for _, row in all_data.iterrows():
            ExpectedGoals.objects.create(
                match=match,
                home=row.get('home', 0),
                away=row.get('away', 0),
                compare_code=row.get('compareCode', 0),
                statistics_type=row.get('statisticsType', ''),
                value_type=row.get('valueType', ''),
                home_value=row.get('homeValue', 0),
                away_value=row.get('awayValue', 0),
                render_type=row.get('renderType', 0),
                key=row.get('key', ''),
                period=row.get('period', 'ALL'),
                group_name=row.get('groupName', ''),
                home_total=row.get('homeTotal', None),
                away_total=row.get('awayTotal', None)
            )
    except Match.DoesNotExist:
        MatchDataError.objects.create(match_id=match_id, error_message=f"Match with ID {match_id} does not exist.")
    except IntegrityError as e:
        MatchDataError.objects.create(match_id=match_id, error_message=f"Database Integrity Error: {e}")
    except Exception as e:
        MatchDataError.objects.create(match_id=match_id, error_message=str(e))
```

### Adım 3: `admin.py` Dosyasını Güncelleme
Admin paneline `ExpectedGoals` ve `MatchDataError` modellerini ekleyelim.

**admin.py dosyasını güncelle:**

```python
from django.contrib import admin
from .models import Match, ExpectedGoals, MatchDataError

@admin.register(ExpectedGoals)
class ExpectedGoalsAdmin(admin.ModelAdmin):
    list_display = ('match', 'home', 'away', 'statistics_type', 'value_type', 'period', 'group_name')
    search_fields = ('match__id', 'key', 'group_name')
    list_filter = ('statistics_type', 'period', 'group_name')
    ordering = ('-match__id',)

@admin.register(MatchDataError)
class MatchDataErrorAdmin(admin.ModelAdmin):
    list_display = ('match_id', 'error_message', 'timestamp')
    search_fields = ('match_id',)
    ordering = ('-timestamp',)
```

### Adım 4: `Celery` Konfigürasyonunu Yapmak
- Celery'nin çalıştığından emin ol ve terminalden `celery -A <proje_adı> worker --loglevel=info` ve `celery -A <proje_adı> beat --loglevel=info` komutlarını çalıştırarak işlemleri başlat.

### Adım 5: Görevi Çağırma
Celery görevini çağırmak için, Django shell veya bir API üzerinden:

```python
from <uygulama_adı>.tasks import fetch_match_statistics
fetch_match_statistics.delay(match_id=12436927)
```

Bu adımlarla birlikte, `fetch_match_statistics` görevi API'den veriyi alacak ve `ExpectedGoals` modeline ekleyecek. Herhangi bir hata oluşursa, `MatchDataError` modeline hata bilgisi kaydedilecek.

***Soru:*** django sheel i nasıl açacağım

**Cevap:** Django shell'i açmak için terminal veya komut satırından aşağıdaki komutu kullanabilirsin:

```bash
python manage.py shell
```

Bu komutu çalıştırdığında, Django shell'e (etkileşimli Python kabuğu) gireceksin ve bu ortamda Django projene ait modeller, veritabanı sorguları ve diğer işlemleri yapabilirsin.

### Örnek Kullanım:
1. **Django Proje Dizini**: Öncelikle `manage.py` dosyanın bulunduğu proje dizinine git:

   ```bash
   cd /path/to/your/project  # Örneğin: cd /home/ahmety/Masaüstü/DjangoPro/sofa
   ```

2. **Django Shell'i Başlat**: 

   ```bash
   python manage.py shell
   ```

3. **Shell İçerisinde İşlemler Yapma**:
   Django shell açıldıktan sonra aşağıdaki gibi modellerine erişebilir ve işlemler yapabilirsin:

   ```python
   from <uygulama_adı>.models import Match, ExpectedGoals
   # Örneğin:
   from football.models import Match, ExpectedGoals

   # Bir maç kaydını çekme
   match = Match.objects.get(id=12436927)
   print(match)
   ```

Eğer virtual environment (sanal ortam) kullanıyorsan, öncelikle sanal ortamı aktif hale getirdiğinden emin olmalısın:

```bash
source /path/to/your/virtualenv/bin/activate  # Örneğin: source /home/ahmety/Masaüstü/myenv/bin/activate
```

Bu şekilde Django shell'i açarak projende etkileşimli olarak işlem yapabilirsin.

***Soru:*** In [1]: from sofa.tasks import fetch_match_statistics
---------------------------------------------------------------------------
ModuleNotFoundError                       Traceback (most recent call last)
Cell In[1], line 1
----> 1 from sofa.tasks import fetch_match_statistics

ModuleNotFoundError: No module named 'sofa.tasks'

**Cevap:** Bu hatanın nedeni, `sofa` uygulamasının ya da `tasks.py` dosyasının Django projesi içinde düzgün bir şekilde tanımlanmamış veya yükleme sırasında bir sorun yaşanmış olmasından kaynaklanıyor olabilir. Aşağıda bu hatayı gidermek için birkaç adım ve öneri bulabilirsin:

### Adım 1: `sofa` Uygulamasının Projeye Eklenmiş Olduğundan Emin Ol

1. `settings.py` dosyasını aç ve `INSTALLED_APPS` kısmında `sofa` uygulamasının eklenmiş olduğundan emin ol.

   ```python
   INSTALLED_APPS = [
       ...
       'sofa',
       ...
   ]
   ```

2. Eğer `sofa` uygulaması ekli değilse `INSTALLED_APPS`'a `sofa`'yı ekle ve ardından migrate işlemlerini yap:

   ```bash
   python manage.py makemigrations
   python manage.py migrate
   ```

### Adım 2: `tasks.py` Dosyasının Doğru Konumda Olduğunu Kontrol Et

`sofa` uygulamasının kök dizininde (`sofa/`) `tasks.py` dosyasının olduğundan emin ol. Uygulama yapısının aşağıdaki gibi göründüğünden emin ol:

```
sofa/
│
├── __init__.py
├── admin.py
├── apps.py
├── models.py
├── tasks.py     # Bu dosyanın burada olduğundan emin ol.
└── views.py
```

Eğer `tasks.py` dosyası burada değilse, doğru konuma taşı ve içerisine Celery görevlerini ekle.

### Adım 3: Python Yolunu ve Ortamını Kontrol Et

Eğer doğru dosya yapısı varsa ve `sofa` modülü `INSTALLED_APPS`'a ekliyse, sorunun nedeni Python yolunun (`PYTHONPATH`) doğru ayarlanmamış olması olabilir. Shell ortamında `PYTHONPATH`'in doğru dizine ayarlandığından emin ol:

1. `manage.py` dosyanın bulunduğu dizine git:

   ```bash
   cd /home/ahmety/Masaüstü/DjangoPro/sofa  # Örneğin proje dizinine git
   ```

2. Django shell'i başlat:

   ```bash
   python manage.py shell
   ```

3. Tekrar `fetch_match_statistics` fonksiyonunu çağır:

   ```python
   from sofa.tasks import fetch_match_statistics
   ```

### Adım 4: `__init__.py` Dosyasının Var Olduğunu Kontrol Et

`sofa` dizininde ve tüm alt dizinlerde `__init__.py` dosyasının olduğundan emin ol. Bu dosya, ilgili dizini bir Python modülü olarak tanımlar. Eğer eksikse, boş bir `__init__.py` dosyası oluştur.

### Adım 5: Django Projesini ve Celery Yapılandırmasını Kontrol Et

1. Eğer hala `ModuleNotFoundError` alıyorsan, Django'nun uygulama yolunu doğru algılayamadığı anlamına gelebilir. Bu durumda `PYTHONPATH` ayarını manuel olarak yapmayı deneyebilirsin:

   ```python
   import sys
   sys.path.append('/home/ahmety/Masaüstü/DjangoPro/sofa')
   from sofa.tasks import fetch_match_statistics
   ```

2. Ayrıca Celery yapılandırmasında `tasks.py` dosyasını tanımladığından emin ol. Örneğin:

   ```python
   app.autodiscover_tasks(['sofa'])
   ```

### Adım 6: Sanal Ortamın Aktif Olduğundan Emin Ol

Eğer sanal ortam kullanıyorsan, sanal ortamın aktif olduğundan ve `sofa` uygulamasının bu ortamda tanındığından emin ol. Sanal ortamı etkinleştirdikten sonra tekrar shell'e gir ve işlemleri yap:

```bash
source /home/ahmety/Masaüstü/myenv/bin/activate  # Sanal ortamını aktif hale getir
python manage.py shell
```

Bu adımları uyguladıktan sonra `sofa` uygulamasını ve `tasks.py` fonksiyonunu sorunsuz bir şekilde import edebilmen gerekir.

***Soru:*** <AsyncResult: b4d2447b-e6d2-47f5-a787-0bfe70fe6163>  bu datayı nasıl göreceğşmm ve nerede

**Cevap:** Bu, Celery tarafından bir görev çalıştırıldığında döndürülen bir `AsyncResult` nesnesidir. Bu nesne, görev durumunu (pending, started, success, failure vb.) ve görev sonucunu kontrol etmek için kullanılır. `AsyncResult` nesnesini kullanarak görev hakkında daha fazla bilgi edinebilir ve sonucunu görebilirsin.

### 1. Görev Sonucunu Kontrol Etmek
Görev sonucunu almak için `AsyncResult` nesnesini kullanarak aşağıdaki adımları izleyebilirsin:

#### Django Shell Üzerinde Görev Durumunu ve Sonucunu Kontrol Etmek
Django shell üzerinden `AsyncResult` nesnesini çağırarak görevin durumunu ve sonucunu kontrol edebilirsin:

```bash
python manage.py shell
```

Sonrasında shell içinde aşağıdaki kodları çalıştır:

```python
from celery.result import AsyncResult
from your_project_name.celery import app  # Projende Celery uygulamasının olduğu yeri içe aktar

# Görevin ID'sini kullanarak AsyncResult nesnesi oluştur
task_id = "b4d2447b-e6d2-47f5-a787-0bfe70fe6163"  # Kendi task ID'ni buraya koy
result = AsyncResult(task_id, app=app)

# Görevin durumunu kontrol et
print(f"Task State: {result.state}")  # Örneğin: "SUCCESS", "FAILURE", "PENDING"

# Görevin sonucunu kontrol et
if result.state == 'SUCCESS':
    print(f"Task Result: {result.result}")
elif result.state == 'FAILURE':
    print(f"Task Failed: {result.result}")
```

Bu şekilde, `result.state` ile görevin durumunu ve `result.result` ile görevin sonucunu görebilirsin.

### 2. Görev Sonucunu Programatik Olarak Kontrol Etmek
Görev sonuçlarını kod içinde programatik olarak da kontrol edebilirsin:

```python
from celery.result import AsyncResult
from your_project_name.celery import app

# AsyncResult nesnesini oluştur ve durumunu kontrol et
task_id = "b4d2447b-e6d2-47f5-a787-0bfe70fe6163"
result = AsyncResult(task_id, app=app)

# Görevin sonucunu almak
if result.ready():
    print("Görev tamamlandı!")
    print(f"Sonuç: {result.result}")
else:
    print(f"Görev henüz tamamlanmadı. Durum: {result.state}")
```

Bu kod, görevin durumunu kontrol eder ve görevin tamamlanıp tamamlanmadığını (`result.ready()`) öğrenir. Eğer görev tamamlandıysa, sonucu (`result.result`) alır.

### 3. Celery Flower ile Görevleri Görüntüleme
Eğer `Celery Flower` kullanıyorsan, görevleri web arayüzünden daha kolay bir şekilde görüntüleyebilirsin:

1. Celery Flower'ı başlatmak için terminalden şu komutu çalıştır:

   ```bash
   celery -A your_project_name flower
   ```

2. Tarayıcıda `http://localhost:5555` adresine git ve buradan görevlerin durumlarını, çalışma sürelerini ve hata mesajlarını görüntüleyebilirsin.

### 4. Celery Loglarındaki Görev Durumunu Kontrol Etme
Celery logları, görevlerin durumunu ve hata mesajlarını görebileceğin başka bir yerdir. Eğer `celery worker` ve `celery beat` işlemlerini başlattıysan, terminalde çalışan bu işlemlerin loglarına bakarak görevlerin nasıl sonuçlandığını görebilirsin.

Örneğin:

```bash
celery -A your_project_name worker --loglevel=info
```

Bu loglarda görevlerin başlama, tamamlama ve hata durumlarını görebilirsin.

### 5. Django Admin Panelinde Görev Hatalarını Görüntüleme
Eğer hata durumlarını `MatchDataError` modeline kaydettiysen, bu hataları Django admin panelinden görüntüleyebilirsin:

1. Admin paneline git (`http://localhost:8000/admin/`).
2. `MatchDataError` modelini seç ve görev hatalarını buradan görüntüle.

Bu adımları takip ederek `AsyncResult` nesnesi ile dönen görevin sonucunu ve durumunu görüntüleyebilirsin.

***Soru:*** new_class._meta.apps.register_model(new_class._meta.app_label, new_class)
/home/ahmety/Masaüstü/myenv/lib/python3.12/site-packages/django/db/models/base.py:366: RuntimeWarning: Model 'data.matchdataerror' was already registered. Reloading models is not advised as it can lead to inconsistencies, most notably with related models.
  new_class._meta.apps.register_model(new_class._meta.app_label, new_class)
It is impossible to add a non-nullable field 'match_id' to matchdataerror without specifying a default. This is because the database needs something to populate existing rows.
Please select a fix:
 1) Provide a one-off default now (will be set on all existing rows with a null value for this column)
 2) Quit and manually define a default value in models.py.

**Cevap:** Bu hata, `match_id` alanının `MatchDataError` modeline eklenirken veritabanındaki mevcut kayıtlarda bu alanın doldurulması gerektiği için oluşuyor. Django, veritabanında bu alana varsayılan bir değer atanmadığı için tüm mevcut satırlarda bu alanı nasıl dolduracağını bilemiyor ve bu durumu çözmek için iki seçenek sunuyor:

1. **Bir defalık varsayılan bir değer atama**: Django, tüm mevcut satırlara bir varsayılan değer atar ve bu işlem sonrasında `match_id` alanı eklendiğinde hatasız bir şekilde veritabanına eklenmiş olur.
2. **Manuel olarak `models.py` dosyasında varsayılan bir değer tanımlama**: `models.py` dosyasında `match_id` alanına varsayılan bir değer tanımlanabilir.

### Çözüm 1: Bir Defalık Varsayılan Değer Atama
Eğer `manage.py` terminal ekranında hata mesajı bu şekilde görünüyorsa:

```bash
Please select a fix:
 1) Provide a one-off default now (will be set on all existing rows with a null value for this column)
 2) Quit and manually define a default value in models.py.
```

Bu durumda `1` tuşuna basarak bir defalık varsayılan değer atayabilirsin. Django senden bir varsayılan değer isteyecek ve bu değeri tüm mevcut satırlarda `match_id` sütununa ekleyecektir. Örneğin:

```bash
Select an option: 1
Please enter the default value now, as valid Python
>>> 0  # (örneğin varsayılan değer olarak 0 girilebilir)
```

Bu şekilde tüm mevcut kayıtlara `match_id` sütunu için 0 değeri atanır ve migrate işlemi başarılı bir şekilde tamamlanır.

### Çözüm 2: `models.py` Dosyasına Varsayılan Değer Tanımlama
`models.py` dosyasına giderek `MatchDataError` modelindeki `match_id` alanına bir varsayılan değer ekleyebilirsin. Örneğin:

```python
class MatchDataError(models.Model):
    match_id = models.IntegerField(verbose_name="Match ID", default=0)  # default=0 eklendi
    error_message = models.TextField(verbose_name="Error Message")
    timestamp = models.DateTimeField(auto_now_add=True, verbose_name="Timestamp")
```

Bu işlemden sonra migrate işlemlerini tekrar yapabilirsin:

```bash
python manage.py makemigrations
python manage.py migrate
```

### Çözüm 3: `null=True` ve `blank=True` Eklemek
Eğer `match_id` sütununun `null` değerleri kabul etmesini istiyorsan, bu sütunu `null=True` ve `blank=True` parametreleri ile güncelleyebilirsin:

```python
class MatchDataError(models.Model):
    match_id = models.IntegerField(verbose_name="Match ID", null=True, blank=True)  # null ve blank eklendi
    error_message = models.TextField(verbose_name="Error Message")
    timestamp = models.DateTimeField(auto_now_add=True, verbose_name="Timestamp")
```

Bu durumda mevcut satırlarda `match_id` alanı `null` olabilir ve herhangi bir varsayılan değer girmene gerek kalmaz. Bu işlemden sonra yine migrate işlemini gerçekleştir:

```bash
python manage.py makemigrations
python manage.py migrate
```

### Ekstra Not: Hata Mesajı `Model Already Registered`
`RuntimeWarning: Model 'data.matchdataerror' was already registered.` hatası ise, modelin birden fazla kez kayıt edilmeye çalışıldığını gösteriyor. Bu hatayı çözmek için:

1. `admin.py` dosyasını kontrol et ve `MatchDataError` modelinin yalnızca bir kez kaydedildiğinden emin ol.
2. `apps.py` veya başka dosyalarda aynı modelin `admin.site.register` veya `@admin.register()` dekoratörü ile birden fazla kez kayıtlı olmadığından emin ol.

Bu adımlar, `match_id` ekleme işlemini ve ilgili modelin doğru kaydedilmesini sağlayacaktır.

***Soru:*** File "/home/ahmety/Masaüstü/myenv/lib/python3.12/site-packages/django/db/backends/base/schema.py", line 330, in _iter_column_sql
    default_value = self.effective_default(field)
                    ^^^^^^^^^^^^^^^^^^^^^^^^^^^^^
  File "/home/ahmety/Masaüstü/myenv/lib/python3.12/site-packages/django/db/backends/base/schema.py", line 483, in effective_default
    return field.get_db_prep_save(self._effective_default(field), self.connection)
           ^^^^^^^^^^^^^^^^^^^^^^^^^^^^^^^^^^^^^^^^^^^^^^^^^^^^^^^^^^^^^^^^^^^^^^^
  File "/home/ahmety/Masaüstü/myenv/lib/python3.12/site-packages/django/db/models/fields/__init__.py", line 1008, in get_db_prep_save
    return self.get_db_prep_value(value, connection=connection, prepared=False)
           ^^^^^^^^^^^^^^^^^^^^^^^^^^^^^^^^^^^^^^^^^^^^^^^^^^^^^^^^^^^^^^^^^^^^
  File "/home/ahmety/Masaüstü/myenv/lib/python3.12/site-packages/django/db/models/fields/__init__.py", line 1677, in get_db_prep_value
    value = self.get_prep_value(value)
            ^^^^^^^^^^^^^^^^^^^^^^^^^^
  File "/home/ahmety/Masaüstü/myenv/lib/python3.12/site-packages/django/db/models/fields/__init__.py", line 1655, in get_prep_value
    value = super().get_prep_value(value)
            ^^^^^^^^^^^^^^^^^^^^^^^^^^^^^
  File "/home/ahmety/Masaüstü/myenv/lib/python3.12/site-packages/django/db/models/fields/__init__.py", line 1531, in get_prep_value
    return self.to_python(value)
           ^^^^^^^^^^^^^^^^^^^^^
  File "/home/ahmety/Masaüstü/myenv/lib/python3.12/site-packages/django/db/models/fields/__init__.py", line 1616, in to_python
    parsed = parse_datetime(value)
             ^^^^^^^^^^^^^^^^^^^^^
  File "/home/ahmety/Masaüstü/myenv/lib/python3.12/site-packages/django/utils/dateparse.py", line 114, in parse_datetime
    return datetime.datetime.fromisoformat(value)
           ^^^^^^^^^^^^^^^^^^^^^^^^^^^^^^^^^^^^^^
TypeError: fromisoformat: argument must be str
(myenv) root@ahmety-Lenovo-V15-G3-IAP:/home/ahmety/Masaüstü/DjangoPro# python manage.py migrate
/home/ahmety/Masaüstü/myenv/lib/python3.12/site-packages/django/db/models/base.py:366: RuntimeWarning: Model 'data.expectedgoals' was already registered. Reloading models is not advised as it can lead to inconsistencies, most notably with related models.
  new_class._meta.apps.register_model(new_class._meta.app_label, new_class)
/home/ahmety/Masaüstü/myenv/lib/python3.12/site-packages/django/db/models/base.py:366: RuntimeWarning: Model 'data.matchdataerror' was already registered. Reloading models is not advised as it can lead to inconsistencies, most notably with related models.
  new_class._meta.apps.register_model(new_class._meta.app_label, new_class)
Operations to perform:
  Apply all migrations: admin, auth, contenttypes, data, django_celery_beat, django_celery_results, sessions
Running migrations:
  Applying data.0004_alter_matchdataerror_options_and_more...Traceback (most recent call last):
  File "/home/ahmety/Masaüstü/DjangoPro/manage.py", line 22, in <module>
    main()
  File "/home/ahmety/Masaüstü/DjangoPro/manage.py", line 18, in main
    execute_from_command_line(sys.argv)
  File "/home/ahmety/Masaüstü/myenv/lib/python3.12/site-packages/django/core/management/__init__.py", line 442, in execute_from_command_line
    utility.execute()
  File "/home/ahmety/Masaüstü/myenv/lib/python3.12/site-packages/django/core/management/__init__.py", line 436, in execute
    self.fetch_command(subcommand).run_from_argv(self.argv)
  File "/home/ahmety/Masaüstü/myenv/lib/python3.12/site-packages/django/core/management/base.py", line 413, in run_from_argv
    self.execute(*args, **cmd_options)
  File "/home/ahmety/Masaüstü/myenv/lib/python3.12/site-packages/django/core/management/base.py", line 459, in execute
    output = self.handle(*args, **options)
             ^^^^^^^^^^^^^^^^^^^^^^^^^^^^^
  File "/home/ahmety/Masaüstü/myenv/lib/python3.12/site-packages/django/core/management/base.py", line 107, in wrapper
    res = handle_func(*args, **kwargs)
          ^^^^^^^^^^^^^^^^^^^^^^^^^^^^
  File "/home/ahmety/Masaüstü/myenv/lib/python3.12/site-packages/django/core/management/commands/migrate.py", line 357, in handle
    post_migrate_state = executor.migrate(
                         ^^^^^^^^^^^^^^^^^
  File "/home/ahmety/Masaüstü/myenv/lib/python3.12/site-packages/django/db/migrations/executor.py", line 135, in migrate
    state = self._migrate_all_forwards(
            ^^^^^^^^^^^^^^^^^^^^^^^^^^^
  File "/home/ahmety/Masaüstü/myenv/lib/python3.12/site-packages/django/db/migrations/executor.py", line 167, in _migrate_all_forwards
    state = self.apply_migration(
            ^^^^^^^^^^^^^^^^^^^^^
  File "/home/ahmety/Masaüstü/myenv/lib/python3.12/site-packages/django/db/migrations/executor.py", line 255, in apply_migration
    state = migration.apply(state, schema_editor)
            ^^^^^^^^^^^^^^^^^^^^^^^^^^^^^^^^^^^^^
  File "/home/ahmety/Masaüstü/myenv/lib/python3.12/site-packages/django/db/migrations/migration.py", line 132, in apply
    operation.database_forwards(
  File "/home/ahmety/Masaüstü/myenv/lib/python3.12/site-packages/django/db/migrations/operations/fields.py", line 110, in database_forwards
    schema_editor.add_field(
  File "/home/ahmety/Masaüstü/myenv/lib/python3.12/site-packages/django/db/backends/base/schema.py", line 722, in add_field
    definition, params = self.column_sql(model, field, include_default=True)
                         ^^^^^^^^^^^^^^^^^^^^^^^^^^^^^^^^^^^^^^^^^^^^^^^^^^^
  File "/home/ahmety/Masaüstü/myenv/lib/python3.12/site-packages/django/db/backends/base/schema.py", line 383, in column_sql
    " ".join(
  File "/home/ahmety/Masaüstü/myenv/lib/python3.12/site-packages/django/db/backends/base/schema.py", line 330, in _iter_column_sql
    default_value = self.effective_default(field)
                    ^^^^^^^^^^^^^^^^^^^^^^^^^^^^^
  File "/home/ahmety/Masaüstü/myenv/lib/python3.12/site-packages/django/db/backends/base/schema.py", line 483, in effective_default
    return field.get_db_prep_save(self._effective_default(field), self.connection)
           ^^^^^^^^^^^^^^^^^^^^^^^^^^^^^^^^^^^^^^^^^^^^^^^^^^^^^^^^^^^^^^^^^^^^^^^
  File "/home/ahmety/Masaüstü/myenv/lib/python3.12/site-packages/django/db/models/fields/__init__.py", line 1008, in get_db_prep_save
    return self.get_db_prep_value(value, connection=connection, prepared=False)
           ^^^^^^^^^^^^^^^^^^^^^^^^^^^^^^^^^^^^^^^^^^^^^^^^^^^^^^^^^^^^^^^^^^^^
  File "/home/ahmety/Masaüstü/myenv/lib/python3.12/site-packages/django/db/models/fields/__init__.py", line 1677, in get_db_prep_value
    value = self.get_prep_value(value)
            ^^^^^^^^^^^^^^^^^^^^^^^^^^
  File "/home/ahmety/Masaüstü/myenv/lib/python3.12/site-packages/django/db/models/fields/__init__.py", line 1655, in get_prep_value
    value = super().get_prep_value(value)
            ^^^^^^^^^^^^^^^^^^^^^^^^^^^^^
  File "/home/ahmety/Masaüstü/myenv/lib/python3.12/site-packages/django/db/models/fields/__init__.py", line 1531, in get_prep_value
    return self.to_python(value)
           ^^^^^^^^^^^^^^^^^^^^^
  File "/home/ahmety/Masaüstü/myenv/lib/python3.12/site-packages/django/db/models/fields/__init__.py", line 1616, in to_python
    parsed = parse_datetime(value)
             ^^^^^^^^^^^^^^^^^^^^^
  File "/home/ahmety/Masaüstü/myenv/lib/python3.12/site-packages/django/utils/dateparse.py", line 114, in parse_datetime
    return datetime.datetime.fromisoformat(value)
           ^^^^^^^^^^^^^^^^^^^^^^^^^^^^^^^^^^^^^^
TypeError: fromisoformat: argument must be str

**Cevap:** Bu hata, veritabanı işlemi sırasında bir tarih veya tarih saat (`datetime`) alanına geçersiz bir değer (string olmayan bir veri türü) geçildiğinde ortaya çıkar. Yani, Django `datetime` alanına `fromisoformat()` ile bir tarih işlemi yapmaya çalışırken, string bir format bekliyor fakat string dışında bir veri türü alıyor. Bu yüzden `TypeError: fromisoformat: argument must be str` hatası alıyorsun.

Bu hatayı çözmek için aşağıdaki adımları uygulayabilirsin:

### Adım 1: Migrate İşlemi Sırasında Varsayılan Değer Sorununu Kontrol Et
`migrate` işlemi sırasında bir tarih veya `datetime` alanına varsayılan değer atanmaya çalışılıyor olabilir. `models.py` dosyasındaki tarih veya `datetime` alanlarını kontrol et ve `default` veya `null=True` ekleyerek sorunu çözebilirsin.

Örneğin:

```python
startTimestamp = models.DateTimeField(null=True, blank=True)  # null ve blank ekleyerek boş değer kabul etmesini sağlıyoruz
```

Eğer `default` bir değer eklemek istiyorsan, `datetime.now` kullanabilirsin:

```python
from django.utils import timezone

startTimestamp = models.DateTimeField(default=timezone.now, null=True, blank=True)
```

Bu, veritabanındaki mevcut kayıtlarda `startTimestamp` veya diğer datetime alanlarına `default` bir değer atayacaktır.

### Adım 2: Geçersiz Tarih Formatı Sorununu Kontrol Et
Hatanın kaynağı, `DateField` veya `DateTimeField` alanlarına `None` veya string olmayan bir değer girilmesinden kaynaklanıyor olabilir. `models.py` dosyasındaki tarih ve `datetime` alanlarını kontrol et ve bu alanlara geçersiz bir veri girmediğinden emin ol.

Örneğin, `models.py` dosyanda `startTimestamp` alanını şu şekilde kontrol et:

```python
from django.db import models
from django.utils import timezone

class Match(models.Model):
    Tarih = models.DateField(null=True, blank=True)  # Tarih alanı için null ve blank ekleyerek geçersiz verileri kabul etmemesi sağlanır.
    customId = models.CharField(max_length=10)
    id = models.BigIntegerField(primary_key=True, unique=True)
    startTimestamp = models.DateTimeField(default=timezone.now, null=True, blank=True)  # Geçerli bir varsayılan datetime değeri atandı.
```

### Adım 3: `makemigrations` ve `migrate` İşlemlerini Tekrar Yap
`models.py` dosyasını güncelledikten sonra aşağıdaki adımları uygula:

```bash
python manage.py makemigrations
python manage.py migrate
```

Bu adımlar, `default` değerler ve `null=True` ayarlarıyla veritabanındaki alanları güncelleyerek hatanın çözülmesini sağlayacaktır.

### Adım 4: Mevcut Kayıtları Kontrol Et ve Güncelle
Eğer mevcut veritabanındaki kayıtlarda `datetime` alanında geçersiz veriler varsa, bu verileri manuel olarak güncellemek gerekebilir. Bunun için Django shell üzerinden aşağıdaki adımları takip edebilirsin:

1. Django shell'i başlat:

    ```bash
    python manage.py shell
    ```

2. Shell üzerinde `Match` modelindeki tüm `datetime` alanlarını kontrol et:

    ```python
    from data.models import Match
    from django.utils import timezone

    # Tüm maç kayıtlarını al ve startTimestamp alanını kontrol et
    for match in Match.objects.all():
        if not isinstance(match.startTimestamp, timezone.datetime):
            match.startTimestamp = timezone.now()
            match.save()
    ```

Bu şekilde tüm kayıtların geçerli bir `datetime` değerine sahip olduğundan emin olabilirsin.

### Adım 5: Migrations Dosyalarını Temizle ve Yeniden Oluştur
Eğer yukarıdaki adımlar sorunu çözmezse, `migrations` dosyalarını temizleyip tekrar oluşturarak bu sorunu çözebilirsin:

1. `migrations` dosyalarını temizle:

    Projendeki `migrations` klasörünü ve içindeki tüm dosyaları (kök `__init__.py` dosyası hariç) sil:

    ```bash
    rm -rf /home/ahmety/Masaüstü/DjangoPro/sofa/migrations/*
    ```

2. `migrate` işlemlerini sıfırdan oluştur:

    ```bash
    python manage.py makemigrations
    python manage.py migrate
    ```

### Adım 6: Sorun Devam Ediyorsa Veritabanını Sıfırla
Eğer sorun devam ediyorsa veritabanını sıfırlayıp tekrar oluşturmak sorunu çözebilir. Bunun için mevcut veritabanını silip yeni bir veritabanı oluşturabilirsin:

```bash
python manage.py flush  # Tüm veritabanı verilerini siler
python manage.py migrate  # Yeni veritabanı şeması oluşturur
```

Bu adımlar, geçersiz tarih formatı ve `TypeError` hatasını çözmene yardımcı olacaktır.

***Soru:*** ^^^^^^^^^^^^^^^^^^^^^^^^^^^^^^^^^^^^^
  File "/home/ahmety/Masaüstü/myenv/lib/python3.12/site-packages/django/db/migrations/migration.py", line 132, in apply
    operation.database_forwards(
  File "/home/ahmety/Masaüstü/myenv/lib/python3.12/site-packages/django/db/migrations/operations/fields.py", line 110, in database_forwards
    schema_editor.add_field(
  File "/home/ahmety/Masaüstü/myenv/lib/python3.12/site-packages/django/db/backends/base/schema.py", line 722, in add_field
    definition, params = self.column_sql(model, field, include_default=True)
                         ^^^^^^^^^^^^^^^^^^^^^^^^^^^^^^^^^^^^^^^^^^^^^^^^^^^
  File "/home/ahmety/Masaüstü/myenv/lib/python3.12/site-packages/django/db/backends/base/schema.py", line 383, in column_sql
    " ".join(
  File "/home/ahmety/Masaüstü/myenv/lib/python3.12/site-packages/django/db/backends/base/schema.py", line 330, in _iter_column_sql
    default_value = self.effective_default(field)
                    ^^^^^^^^^^^^^^^^^^^^^^^^^^^^^
  File "/home/ahmety/Masaüstü/myenv/lib/python3.12/site-packages/django/db/backends/base/schema.py", line 483, in effective_default
    return field.get_db_prep_save(self._effective_default(field), self.connection)
           ^^^^^^^^^^^^^^^^^^^^^^^^^^^^^^^^^^^^^^^^^^^^^^^^^^^^^^^^^^^^^^^^^^^^^^^
  File "/home/ahmety/Masaüstü/myenv/lib/python3.12/site-packages/django/db/models/fields/__init__.py", line 1008, in get_db_prep_save
    return self.get_db_prep_value(value, connection=connection, prepared=False)
           ^^^^^^^^^^^^^^^^^^^^^^^^^^^^^^^^^^^^^^^^^^^^^^^^^^^^^^^^^^^^^^^^^^^^
  File "/home/ahmety/Masaüstü/myenv/lib/python3.12/site-packages/django/db/models/fields/__init__.py", line 1677, in get_db_prep_value
    value = self.get_prep_value(value)
            ^^^^^^^^^^^^^^^^^^^^^^^^^^
  File "/home/ahmety/Masaüstü/myenv/lib/python3.12/site-packages/django/db/models/fields/__init__.py", line 1655, in get_prep_value
    value = super().get_prep_value(value)
            ^^^^^^^^^^^^^^^^^^^^^^^^^^^^^
  File "/home/ahmety/Masaüstü/myenv/lib/python3.12/site-packages/django/db/models/fields/__init__.py", line 1531, in get_prep_value
    return self.to_python(value)
           ^^^^^^^^^^^^^^^^^^^^^
  File "/home/ahmety/Masaüstü/myenv/lib/python3.12/site-packages/django/db/models/fields/__init__.py", line 1616, in to_python
    parsed = parse_datetime(value)
             ^^^^^^^^^^^^^^^^^^^^^
  File "/home/ahmety/Masaüstü/myenv/lib/python3.12/site-packages/django/utils/dateparse.py", line 114, in parse_datetime
    return datetime.datetime.fromisoformat(value)
           ^^^^^^^^^^^^^^^^^^^^^^^^^^^^^^^^^^^^^^
TypeError: fromisoformat: argument must be str
(myenv) root@ahmety-Lenovo-V15-G3-IAP:/home/ahmety/Masaüstü/DjangoPro# ^C
(myenv) root@ahmety-Lenovo-V15-G3-IAP:/home/ahmety/Masaüstü/DjangoPro# python manage.py makemigrations
/home/ahmety/Masaüstü/myenv/lib/python3.12/site-packages/django/db/models/base.py:366: RuntimeWarning: Model 'data.expectedgoals' was already registered. Reloading models is not advised as it can lead to inconsistencies, most notably with related models.
  new_class._meta.apps.register_model(new_class._meta.app_label, new_class)
/home/ahmety/Masaüstü/myenv/lib/python3.12/site-packages/django/db/models/base.py:366: RuntimeWarning: Model 'data.matchdataerror' was already registered. Reloading models is not advised as it can lead to inconsistencies, most notably with related models.
  new_class._meta.apps.register_model(new_class._meta.app_label, new_class)
No changes detected
(myenv) root@ahmety-Lenovo-V15-G3-IAP:/home/ahmety/Masaüstü/DjangoPro# python manage.py migrate
/home/ahmety/Masaüstü/myenv/lib/python3.12/site-packages/django/db/models/base.py:366: RuntimeWarning: Model 'data.expectedgoals' was already registered. Reloading models is not advised as it can lead to inconsistencies, most notably with related models.
  new_class._meta.apps.register_model(new_class._meta.app_label, new_class)
/home/ahmety/Masaüstü/myenv/lib/python3.12/site-packages/django/db/models/base.py:366: RuntimeWarning: Model 'data.matchdataerror' was already registered. Reloading models is not advised as it can lead to inconsistencies, most notably with related models.
  new_class._meta.apps.register_model(new_class._meta.app_label, new_class)
Operations to perform:
  Apply all migrations: admin, auth, contenttypes, data, django_celery_beat, django_celery_results, sessions
Running migrations:
  Applying data.0004_alter_matchdataerror_options_and_more...Traceback (most recent call last):
  File "/home/ahmety/Masaüstü/DjangoPro/manage.py", line 22, in <module>
    main()
  File "/home/ahmety/Masaüstü/DjangoPro/manage.py", line 18, in main
    execute_from_command_line(sys.argv)
  File "/home/ahmety/Masaüstü/myenv/lib/python3.12/site-packages/django/core/management/__init__.py", line 442, in execute_from_command_line
    utility.execute()
  File "/home/ahmety/Masaüstü/myenv/lib/python3.12/site-packages/django/core/management/__init__.py", line 436, in execute
    self.fetch_command(subcommand).run_from_argv(self.argv)
  File "/home/ahmety/Masaüstü/myenv/lib/python3.12/site-packages/django/core/management/base.py", line 413, in run_from_argv
    self.execute(*args, **cmd_options)
  File "/home/ahmety/Masaüstü/myenv/lib/python3.12/site-packages/django/core/management/base.py", line 459, in execute
    output = self.handle(*args, **options)
             ^^^^^^^^^^^^^^^^^^^^^^^^^^^^^
  File "/home/ahmety/Masaüstü/myenv/lib/python3.12/site-packages/django/core/management/base.py", line 107, in wrapper
    res = handle_func(*args, **kwargs)
          ^^^^^^^^^^^^^^^^^^^^^^^^^^^^
  File "/home/ahmety/Masaüstü/myenv/lib/python3.12/site-packages/django/core/management/commands/migrate.py", line 357, in handle
    post_migrate_state = executor.migrate(
                         ^^^^^^^^^^^^^^^^^
  File "/home/ahmety/Masaüstü/myenv/lib/python3.12/site-packages/django/db/migrations/executor.py", line 135, in migrate
    state = self._migrate_all_forwards(
            ^^^^^^^^^^^^^^^^^^^^^^^^^^^
  File "/home/ahmety/Masaüstü/myenv/lib/python3.12/site-packages/django/db/migrations/executor.py", line 167, in _migrate_all_forwards
    state = self.apply_migration(
            ^^^^^^^^^^^^^^^^^^^^^
  File "/home/ahmety/Masaüstü/myenv/lib/python3.12/site-packages/django/db/migrations/executor.py", line 255, in apply_migration
    state = migration.apply(state, schema_editor)
            ^^^^^^^^^^^^^^^^^^^^^^^^^^^^^^^^^^^^^
  File "/home/ahmety/Masaüstü/myenv/lib/python3.12/site-packages/django/db/migrations/migration.py", line 132, in apply
    operation.database_forwards(
  File "/home/ahmety/Masaüstü/myenv/lib/python3.12/site-packages/django/db/migrations/operations/fields.py", line 110, in database_forwards
    schema_editor.add_field(
  File "/home/ahmety/Masaüstü/myenv/lib/python3.12/site-packages/django/db/backends/base/schema.py", line 722, in add_field
    definition, params = self.column_sql(model, field, include_default=True)
                         ^^^^^^^^^^^^^^^^^^^^^^^^^^^^^^^^^^^^^^^^^^^^^^^^^^^
  File "/home/ahmety/Masaüstü/myenv/lib/python3.12/site-packages/django/db/backends/base/schema.py", line 383, in column_sql
    " ".join(
  File "/home/ahmety/Masaüstü/myenv/lib/python3.12/site-packages/django/db/backends/base/schema.py", line 330, in _iter_column_sql
    default_value = self.effective_default(field)
                    ^^^^^^^^^^^^^^^^^^^^^^^^^^^^^
  File "/home/ahmety/Masaüstü/myenv/lib/python3.12/site-packages/django/db/backends/base/schema.py", line 483, in effective_default
    return field.get_db_prep_save(self._effective_default(field), self.connection)
           ^^^^^^^^^^^^^^^^^^^^^^^^^^^^^^^^^^^^^^^^^^^^^^^^^^^^^^^^^^^^^^^^^^^^^^^
  File "/home/ahmety/Masaüstü/myenv/lib/python3.12/site-packages/django/db/models/fields/__init__.py", line 1008, in get_db_prep_save
    return self.get_db_prep_value(value, connection=connection, prepared=False)
           ^^^^^^^^^^^^^^^^^^^^^^^^^^^^^^^^^^^^^^^^^^^^^^^^^^^^^^^^^^^^^^^^^^^^
  File "/home/ahmety/Masaüstü/myenv/lib/python3.12/site-packages/django/db/models/fields/__init__.py", line 1677, in get_db_prep_value
    value = self.get_prep_value(value)
            ^^^^^^^^^^^^^^^^^^^^^^^^^^
  File "/home/ahmety/Masaüstü/myenv/lib/python3.12/site-packages/django/db/models/fields/__init__.py", line 1655, in get_prep_value
    value = super().get_prep_value(value)
            ^^^^^^^^^^^^^^^^^^^^^^^^^^^^^
  File "/home/ahmety/Masaüstü/myenv/lib/python3.12/site-packages/django/db/models/fields/__init__.py", line 1531, in get_prep_value
    return self.to_python(value)
           ^^^^^^^^^^^^^^^^^^^^^
  File "/home/ahmety/Masaüstü/myenv/lib/python3.12/site-packages/django/db/models/fields/__init__.py", line 1616, in to_python
    parsed = parse_datetime(value)
             ^^^^^^^^^^^^^^^^^^^^^
  File "/home/ahmety/Masaüstü/myenv/lib/python3.12/site-packages/django/utils/dateparse.py", line 114, in parse_datetime
    return datetime.datetime.fromisoformat(value)
           ^^^^^^^^^^^^^^^^^^^^^^^^^^^^^^^^^^^^^^

**Cevap:** Bu hatanın kaynağı, `DateTimeField` veya `DateField` türünde olan bir alanın veritabanına yanlış bir veri tipi ile kaydedilmeye çalışılmasından kaynaklanıyor. Hata, `fromisoformat()` fonksiyonunun bir `string` formatı beklerken başka bir türle (örneğin `None` veya `int`) karşılaştığında meydana gelir. Bunun çözümü için birkaç adım izleyebiliriz:

### Çözüm Yöntemleri

1. **Mevcut Migrations Dosyalarını Temizle:**
   
   Migration dosyaları ve veritabanı yapısı arasında tutarsızlıklar olabilir. Öncelikle, migration dosyalarını temizleyip yeniden oluşturmayı deneyelim:

   - `migrations` klasörünü sil (kök `__init__.py` dosyasını silme) ve sonra migrate işlemlerini tekrar yap:

     ```bash
     find . -path "*/migrations/*.py" -not -name "__init__.py" -delete
     find . -path "*/migrations/*.pyc"  -delete
     ```

     Ardından, migrate işlemlerini yeniden yap:

     ```bash
     python manage.py makemigrations
     python manage.py migrate
     ```

2. **Hatalı Kayıtları Bul ve Güncelle:**
   
   Hatalı `datetime` veya `date` alanlarını kontrol etmemiz gerekiyor. Bunun için `Django Shell` kullanarak veritabanındaki tüm `datetime` alanlarını kontrol edebilir ve geçerli formatta olmayan kayıtları düzeltebiliriz:

   ```bash
   python manage.py shell
   ```

   Sonrasında `shell` içinde:

   ```python
   from data.models import Match  # Match modelini içe aktar
   from django.utils import timezone

   # Tüm kayıtları al ve startTimestamp alanını kontrol et
   for match in Match.objects.all():
       if not isinstance(match.startTimestamp, timezone.datetime):
           print(f"Hatalı startTimestamp: {match.startTimestamp} (Match ID: {match.id})")
           # Hatalı datetime verisini düzelt
           match.startTimestamp = timezone.now()  # Veya başka geçerli bir datetime değeri
           match.save()
   ```

   Bu, `Match` modelindeki hatalı `datetime` kayıtlarını güncelleyecektir.

3. **Migration Dosyasında `DateTimeField` Varsayılan Değerini Kontrol Et:**
   
   Eğer `Match` modelinde `DateTimeField` türündeki bir alana varsayılan bir değer ekleniyorsa (`default`), bu değerin geçerli bir `datetime` formatında olduğundan emin olmalısın. Örneğin:

   ```python
   from django.utils import timezone

   startTimestamp = models.DateTimeField(default=timezone.now, null=True, blank=True)
   ```

   Bu ayarlama, `datetime` alanının varsayılan değerini geçerli bir `timezone` değeri olarak atar ve hatayı çözer.

4. **Hatalı Varsayılan Değeri `DateTimeField` İçin Kaldır:**
   
   Migration dosyasında `DateTimeField` veya `DateField` için geçersiz bir varsayılan değer tanımlanmış olabilir. Bunun için `migrations` klasöründeki ilgili `migration` dosyasını kontrol et:

   - `data.0004_alter_matchdataerror_options_and_more.py` dosyasını aç ve `startTimestamp` gibi bir alan için geçersiz bir `default` değerin olup olmadığını kontrol et. Eğer varsa, `default` parametresini kaldır veya uygun bir `timezone.now` değeri ile değiştir.

   Örneğin:

   ```python
   # Yanlış olan:
   field=models.DateTimeField(default=""),

   # Doğru olan:
   field=models.DateTimeField(default=timezone.now),
   ```

5. **Mevcut `DateTimeField` veya `DateField` Alanlarına `null=True` ve `blank=True` Ekleme:**

   Eğer `DateTimeField` veya `DateField` alanlarına `None` değer atamak istiyorsan, bu alanları `null=True` ve `blank=True` olarak tanımlaman gerekir:

   ```python
   startTimestamp = models.DateTimeField(null=True, blank=True)  # null ve blank ekle
   ```

   Bu değişikliği yaptıktan sonra migrate işlemini yeniden yap:

   ```bash
   python manage.py makemigrations
   python manage.py migrate
   ```

6. **Mevcut Veritabanı Değerlerini Güncelleme:**
   
   Eğer bu adımlar işe yaramazsa, mevcut veritabanında `startTimestamp` veya `DateTimeField` türündeki alanlarda `None`, `int`, veya başka bir türde veri olma ihtimali var. Bu durumda, SQL veritabanına bağlanarak manuel olarak bu verileri güncellemen gerekebilir:

   ```sql
   UPDATE data_match SET startTimestamp = '2024-01-01 00:00:00' WHERE startTimestamp IS NULL OR startTimestamp = '';
   ```

### Ekstra Not: "Model Already Registered" Hatası
Bu hatayı önlemek için `models.py` veya `admin.py` dosyalarında modellerin birden fazla kez kaydedilmediğinden emin ol. `Model 'data.expectedgoals' was already registered` hatası modelin birden fazla kez kaydedilmesinden kaynaklanıyor olabilir.

Bunun için `admin.py` dosyasını kontrol et ve aynı modelin birden fazla kez kaydedilmediğinden emin ol:

```python
# Yanlış olan:
admin.site.register(ExpectedGoals)
admin.site.register(ExpectedGoals)  # Aynı model iki kez kayıtlı

# Doğru olan:
admin.site.register(ExpectedGoals)  # Tek bir kez kayıtlı
```

Bu adımları uyguladıktan sonra `TypeError: fromisoformat` hatasının çözülmesi gerekiyor. Eğer hata devam ederse, lütfen güncel `models.py` ve `migration` dosyasını paylaş, böylece daha detaylı bir inceleme yapabilirim.

***Soru:*** TypeError at /admin/django_celery_beat/periodictask/
fetch_match_statistics() missing 1 required positional argument: 'match_id'
Request Method:	POST
Request URL:	http://127.0.0.1:8000/admin/django_celery_beat/periodictask/
Django Version:	5.1.1
Exception Type:	TypeError
Exception Value:	
fetch_match_statistics() missing 1 required positional argument: 'match_id'
Exception Location:	/home/ahmety/Masaüstü/myenv/lib/python3.12/site-packages/celery/app/task.py, line 559, in apply_async
Raised during:	django_celery_beat.admin.changelist_view
Python Executable:	/home/ahmety/Masaüstü/myenv/bin/python
Python Version:	3.12.3
Python Path:	
['/home/ahmety/Masaüstü/DjangoPro',
 '/home/ahmety/Masaüstü/DjangoPro',
 '/usr/lib/python312.zip',
 '/usr/lib/python3.12',
 '/usr/lib/python3.12/lib-dynload',
 '/home/ahmety/Masaüstü/myenv/lib/python3.12/site-packages']
Server time:	Sun, 29 Sep 2024 15:00:03 +0300

**Cevap:** Bu hata, Celery görevini çalıştırırken `fetch_match_statistics` fonksiyonuna gerekli olan `match_id` argümanının sağlanmamış olmasından kaynaklanıyor. `fetch_match_statistics` fonksiyonu `match_id` adlı bir zorunlu pozisyonel argüman bekliyor, ancak bu argüman sağlanmadığı için `TypeError` hatası alıyorsun.

`django-celery-beat` ile görev zamanlama yaparken, Celery görevine belirli parametreler (`args`) geçmeniz gerekir. Aşağıdaki adımları takip ederek hatayı çözebilir ve Celery görevine `match_id` parametresini sağlayabilirsin.

### Çözüm 1: `fetch_match_statistics` Görevine `kwargs` Kullanarak `match_id` Parametresini Sağlama

Görevi tanımlarken `kwargs` kullanarak `match_id` parametresini sağla:

1. **tasks.py** dosyasını aç ve `fetch_match_statistics` görevini aşağıdaki şekilde düzenle:

   ```python
   from celery import shared_task

   @shared_task(bind=True)
   def fetch_match_statistics(self, match_id=None):
       if match_id is None:
           raise ValueError("Match ID is required to fetch match statistics.")
       # Geri kalan işlem kodları burada olacak
       print(f"Fetching match statistics for match ID: {match_id}")
       # Maç verilerini işleme ve kaydetme kodlarını ekle
   ```

   Bu düzenlemede `match_id` parametresini `None` varsayılan değeri ile tanımlıyoruz ve `match_id` sağlanmadığında `ValueError` hatası fırlatıyoruz.

2. `kwargs` kullanarak Celery görevini çağırırken `match_id` parametresini geç:

   ```python
   from sofa.tasks import fetch_match_statistics

   # Görevi çalıştırırken `kwargs` ile `match_id` parametresini geçiyoruz
   fetch_match_statistics.apply_async(kwargs={'match_id': 123456})
   ```

### Çözüm 2: `django-celery-beat` Üzerinden Parametreleri Tanımlama

Eğer `django-celery-beat` üzerinden bu görevi zamanlıyorsan, `PeriodicTask` oluştururken `kwargs` veya `args` tanımlaman gerekir:

1. Django admin paneline git ve `django_celery_beat/PeriodTask` sayfasına git.

2. Görev için bir `kwargs` tanımla. Aşağıdaki gibi `kwargs` bölümüne `match_id` ekleyebilirsin:

   **kwargs:**

   ```json
   {"match_id": 123456}
   ```

   Alternatif olarak `args` kullanıyorsan, `args` bölümüne `match_id` ekleyebilirsin:

   **args:**

   ```json
   [123456]
   ```

3. `fetch_match_statistics` görevini `kwargs` veya `args` ile çalışacak şekilde yapılandırdıktan sonra tekrar deneyin.

### Çözüm 3: Celery Görevinde `kwargs` Parametresini Kontrol Etme

`tasks.py` dosyasında `fetch_match_statistics` görevini aşağıdaki gibi tanımlayarak `kwargs` parametresini kontrol edebilir ve `match_id` değerini alabilirsin:

```python
from celery import shared_task

@shared_task(bind=True)
def fetch_match_statistics(self, *args, **kwargs):
    match_id = kwargs.get('match_id', None)
    if not match_id:
        raise ValueError("Match ID is required.")
    # Görev kodları burada çalıştırılır
    print(f"Fetching statistics for match ID: {match_id}")
```

Bu tanımda `kwargs.get('match_id')` ile `match_id`'yi kontrol ediyoruz ve sağlanmadığı durumlarda bir `ValueError` fırlatıyoruz.

### Çözüm 4: `Celery Task` Tanımlamasını Doğru Yaptığınızdan Emin Ol

`fetch_match_statistics` fonksiyonunu çalıştırdığınız yerden (örneğin, başka bir fonksiyon veya `django-celery-beat` konfigürasyonu) görevi şu şekilde çalıştırdığınızdan emin olun:

```python
from sofa.tasks import fetch_match_statistics

# Görev çağrısını `apply_async` veya `delay` metodu ile yapın:
fetch_match_statistics.apply_async(kwargs={'match_id': 123456})
# veya
fetch_match_statistics.delay(match_id=123456)
```

Bu, `kwargs` veya `delay` fonksiyonu ile `match_id`'yi sağladığınızdan emin olmanızı sağlar.

### Çözüm 5: Django Celery Beat'de Görevi Manuel Olarak Yapılandırma

Admin panelde `django_celery_beat.PeriodicTask` kullanıyorsanız, `kwargs` parametresini manuel olarak şu adımları takip ederek ekleyin:

1. **Görev Seçimi ve Zamanlama**: `django_celery_beat.PeriodicTask` sayfasında `fetch_match_statistics` görevini seçin.

2. **kwargs veya args**: `kwargs` bölümünde şu şekilde ekleyin:

   ```json
   {"match_id": 123456}
   ```

3. Kaydet ve görevi çalıştır. Bu işlem `match_id`'yi sağladığınızdan emin olmanızı sağlar.

### Çözüm 6: `fetch_match_statistics` Görevini `args` Kullanarak Çalıştırma

Görevi `args` kullanarak çalıştırmak isterseniz, `fetch_match_statistics` fonksiyonunu aşağıdaki şekilde çağırabilirsiniz:

```python
fetch_match_statistics.apply_async(args=[123456])
```

Bu çağrıda `match_id` değeri pozisyonel bir argüman olarak sağlanır ve hata almazsınız.

Bu adımları takip ederek `fetch_match_statistics` fonksiyonuna `match_id` parametresini ekleyebilir ve hatayı düzeltebilirsin. Eğer başka bir hata ile karşılaşırsan, ilgili `task` fonksiyonu veya `PeriodicTask` konfigürasyonunu daha detaylı inceleyebiliriz.

***Soru:*** FieldError at /admin/data/expectedgoals/
Cannot resolve keyword 'match' into field. Choices are: away, away_total, away_value, compare_code, group_name, home, home_total, home_value, id, key, match_id, period, render_type, statistics_type, value_type
Request Method:	GET
Request URL:	http://127.0.0.1:8000/admin/data/expectedgoals/
Django Version:	5.1.1
Exception Type:	FieldError
Exception Value:	
Cannot resolve keyword 'match' into field. Choices are: away, away_total, away_value, compare_code, group_name, home, home_total, home_value, id, key, match_id, period, render_type, statistics_type, value_type
Exception Location:	/home/ahmety/Masaüstü/myenv/lib/python3.12/site-packages/django/db/models/sql/query.py, line 1768, in names_to_path
Raised during:	django.contrib.admin.options.changelist_view
Python Executable:	/home/ahmety/Masaüstü/myenv/bin/python
Python Version:	3.12.3
Python Path:	
['/home/ahmety/Masaüstü/DjangoPro',
 '/home/ahmety/Masaüstü/DjangoPro',
 '/usr/lib/python312.zip',
 '/usr/lib/python3.12',
 '/usr/lib/python3.12/lib-dynload',
 '/home/ahmety/Masaüstü/myenv/lib/python3.12/site-packages']
Server time:	Sun, 29 Sep 2024 15:01:18 +0300

**Cevap:** Bu hata, `ExpectedGoals` modelinde `match` isimli bir alan bulunmadığı halde `admin.py` veya başka bir yerden bu alanı kullanmaya çalıştığınızda meydana gelir. `ExpectedGoals` modelinde `match` isimli bir alan yerine `match_id` alanı tanımlı olduğundan dolayı Django bu alanı çözümleyemiyor.

### Hatanın Nedeni:
Django admin veya başka bir sorgulama işlemi sırasında `match` alanını kullanmaya çalışıyorsunuz. Ancak, `ExpectedGoals` modelinizde `match` adında bir alan bulunmuyor. Bunun yerine, `match_id` alanı kullanılıyor olabilir. Bu hatayı çözmek için `ExpectedGoals` modelinde `ForeignKey` ile `Match` modeline doğru bir ilişki tanımlamalısınız veya `match` yerine `match_id` kullanmalısınız.

### Çözüm Yöntemleri:

1. **Modeli Güncelleme (ForeignKey İlişkisi Tanımlama)**:
   Eğer `ExpectedGoals` modeli `Match` modeli ile ilişkilendirilmiş bir `ForeignKey` alanı içermiyorsa, `match_id` alanını `ForeignKey` olarak değiştirebilirsiniz. Bu işlem `match` alanını `Match` modeline bağlayacaktır.

   **models.py** dosyasını aç ve `ExpectedGoals` modelindeki `match_id` alanını `ForeignKey` olarak değiştir:

   ```python
   from django.db import models

   class Match(models.Model):
       # Maç modelinin mevcut alanları burada olacak
       id = models.BigIntegerField(primary_key=True)
       # Diğer alanlar...

   class ExpectedGoals(models.Model):
       match = models.ForeignKey(Match, on_delete=models.CASCADE, related_name='expected_goals', verbose_name="Match")  # ForeignKey ekliyoruz
       home = models.FloatField(verbose_name="Home Expected Goals")
       away = models.FloatField(verbose_name="Away Expected Goals")
       compare_code = models.PositiveSmallIntegerField(verbose_name="Compare Code")
       statistics_type = models.CharField(max_length=50, verbose_name="Statistics Type")
       value_type = models.CharField(max_length=50, verbose_name="Value Type")
       home_value = models.FloatField(verbose_name="Home Value")
       away_value = models.FloatField(verbose_name="Away Value")
       render_type = models.PositiveSmallIntegerField(verbose_name="Render Type")
       key = models.CharField(max_length=50, verbose_name="Key")
       period = models.CharField(max_length=20, verbose_name="Period")
       group_name = models.CharField(max_length=50, verbose_name="Group Name")
       home_total = models.FloatField(null=True, blank=True, verbose_name="Home Total")
       away_total = models.FloatField(null=True, blank=True, verbose_name="Away Total")

       class Meta:
           verbose_name = "Expected Goals"
           verbose_name_plural = "Expected Goals"

       def __str__(self):
           return f"Match {self.match.id} - Expected Goals: Home {self.home} vs Away {self.away}"
   ```

   Bu değişikliği yaptıktan sonra `makemigrations` ve `migrate` komutlarını çalıştır:

   ```bash
   python manage.py makemigrations
   python manage.py migrate
   ```

   Bu işlem `ExpectedGoals` modelini `Match` modeli ile ilişkilendirecek ve `match` alanını kullanabilmenizi sağlayacaktır.

2. **Admin Panelindeki `list_display` ve `search_fields` Alanlarını Güncelleme**:
   
   Eğer `ExpectedGoals` modelinizde `match` adında bir alan yoksa, `admin.py` dosyasındaki `list_display`, `search_fields` veya `list_filter` gibi alanlarda `match` yerine `match_id` veya `match` ile ilişkili bir alan kullanmalısınız.

   **admin.py** dosyasını aç ve `ExpectedGoals` modeli için kullanılan `list_display`, `search_fields`, veya `list_filter` alanlarını kontrol et:

   ```python
   from django.contrib import admin
   from .models import ExpectedGoals

   @admin.register(ExpectedGoals)
   class ExpectedGoalsAdmin(admin.ModelAdmin):
       list_display = ('match_id', 'home', 'away', 'statistics_type', 'value_type', 'period', 'group_name')  # 'match' yerine 'match_id' kullan
       search_fields = ('match_id', 'key', 'group_name')  # 'match' yerine 'match_id' kullan
       list_filter = ('statistics_type', 'period', 'group_name')
       ordering = ('-match_id',)
   ```

   Bu düzenleme, `ExpectedGoals` modelinde `match` yerine `match_id` kullanılmasını sağlar ve hatayı çözer.

3. **Django Admin Üzerindeki Görünümleri Güncelleme**:
   
   Eğer `admin.py` dosyasındaki `queryset` veya `form` işlemlerinde `match` kullanıyorsanız, `match_id` ile değiştirmelisiniz:

   ```python
   # Yanlış kullanım:
   queryset = ExpectedGoals.objects.filter(match__homeTeam_name='Team A')

   # Doğru kullanım:
   queryset = ExpectedGoals.objects.filter(match_id__homeTeam_name='Team A')
   ```

   `ExpectedGoals` modelinde `match` yerine `match_id` ile ilgili alanları kullanarak sorgulama yapmalısınız.

4. **Mevcut Migrations Dosyalarını Temizleme ve Yeniden Oluşturma**:
   
   Eğer yukarıdaki adımlar sorunu çözmezse, `migrations` dosyalarını temizleyip tekrar oluşturmayı deneyebilirsiniz. Bunun için:

   ```bash
   find . -path "*/migrations/*.py" -not -name "__init__.py" -delete
   find . -path "*/migrations/*.pyc" -delete
   ```

   Sonrasında tekrar `makemigrations` ve `migrate` işlemlerini yap:

   ```bash
   python manage.py makemigrations
   python manage.py migrate
   ```

Bu adımları takip ederek `FieldError: Cannot resolve keyword 'match' into field` hatasını çözebilirsin. Eğer sorun devam ederse, `ExpectedGoals` ve `Match` modellerini ve `admin.py` dosyasındaki ilgili kodları paylaşarak daha detaylı inceleme yapabiliriz.

***Soru:*** ProgrammingError at /admin/data/matchdataerror/
column data_matchdataerror.match_id does not exist
LINE 1: SELECT "data_matchdataerror"."id", "data_matchdataerror"."ma...
                                           ^
Request Method:	GET
Request URL:	http://127.0.0.1:8000/admin/data/matchdataerror/
Django Version:	5.1.1
Exception Type:	ProgrammingError
Exception Value:	
column data_matchdataerror.match_id does not exist
LINE 1: SELECT "data_matchdataerror"."id", "data_matchdataerror"."ma...
                                           ^
Exception Location:	/home/ahmety/Masaüstü/myenv/lib/python3.12/site-packages/django/db/backends/utils.py, line 105, in _execute
Raised during:	django.contrib.admin.options.changelist_view
Python Executable:	/home/ahmety/Masaüstü/myenv/bin/python
Python Version:	3.12.3
Python Path:	
['/home/ahmety/Masaüstü/DjangoPro',
 '/home/ahmety/Masaüstü/DjangoPro',
 '/usr/lib/python312.zip',
 '/usr/lib/python3.12',
 '/usr/lib/python3.12/lib-dynload',
 '/home/ahmety/Masaüstü/myenv/lib/python3.12/site-packages']
Server time:	Sun, 29 Sep 2024 15:03:41 +0300
Traceback Switch to copy-and-paste view
/home/ahmety/Masaüstü/myenv/lib/python3.12/site-packages/django/db/backends/utils.py, line 105, in _execute
                return self.cursor.execute(sql, params)
                            ^^^^^^^^^^^^^^^^^^^^^^^^^^^^^^^^ …
Local vars
The above exception (column data_matchdataerror.match_id does not exist LINE 1: SELECT "data_matchdataerror"."id", "data_matchdataerror"."ma... ^ ) was the direct cause of the following exception:
/home/ahmety/Masaüstü/myenv/lib/python3.12/site-packages/django/core/handlers/exception.py, line 55, in inner
                response = get_response(request)
                               ^^^^^^^^^^^^^^^^^^^^^ …
Local vars
/home/ahmety/Masaüstü/myenv/lib/python3.12/site-packages/django/core/handlers/base.py, line 197, in _get_response
                response = wrapped_callback(request, *callback_args, **callback_kwargs)
                                ^^^^^^^^^^^^^^^^^^^^^^^^^^^^^^^^^^^^^^^^^^^^^^^^^^^^^^^^^^^^ …
Local vars
/home/ahmety/Masaüstü/myenv/lib/python3.12/site-packages/django/contrib/admin/options.py, line 718, in wrapper
                return self.admin_site.admin_view(view)(*args, **kwargs)
                            ^^^^^^^^^^^^^^^^^^^^^^^^^^^^^^^^^^^^^^^^^^^^^^^^^ …
Local vars
/home/ahmety/Masaüstü/myenv/lib/python3.12/site-packages/django/utils/decorators.py, line 188, in _view_wrapper
                        result = _process_exception(request, e)
                                      ^^^^^^^^^^^^^^^^^^^^^^^^^^^^^^ …
Local vars
/home/ahmety/Masaüstü/myenv/lib/python3.12/site-packages/django/utils/decorators.py, line 186, in _view_wrapper
                        response = view_func(request, *args, **kwargs)
                                        ^^^^^^^^^^^^^^^^^^^^^^^^^^^^^^^^^^^ …
Local vars
/home/ahmety/Masaüstü/myenv/lib/python3.12/site-packages/django/views/decorators/cache.py, line 80, in _view_wrapper
            response = view_func(request, *args, **kwargs)
                           ^^^^^^^^^^^^^^^^^^^^^^^^^^^^^^^^^^^ …
Local vars
/home/ahmety/Masaüstü/myenv/lib/python3.12/site-packages/django/contrib/admin/sites.py, line 241, in inner
            return view(request, *args, **kwargs)
                        ^^^^^^^^^^^^^^^^^^^^^^^^^^^^^^ …
Local vars
/home/ahmety/Masaüstü/myenv/lib/python3.12/site-packages/django/utils/decorators.py, line 48, in _wrapper
        return bound_method(*args, **kwargs)
                   ^^^^^^^^^^^^^^^^^^^^^^^^^^^^^

**Cevap:** Bu hata, `MatchDataError` modelinde `match_id` adlı bir sütunun veritabanında olmadığını ve Django'nun bu sütunu sorgularken bulamadığını gösterir. Bunun nedeni, `match_id` alanı eklenmiş olmasına rağmen veritabanına doğru bir şekilde yansıtılmamış olması olabilir. Bu durumu çözmek için aşağıdaki adımları takip edebilirsin:

### 1. Mevcut `makemigrations` ve `migrate` İşlemlerini Kontrol Etme
Öncelikle, `models.py` dosyasındaki `MatchDataError` modelini kontrol et ve `match_id` alanının tanımlandığından emin ol. Daha sonra `makemigrations` ve `migrate` işlemlerini tekrar yaparak bu alanın veritabanına eklenmesini sağla:

1. **`models.py` Dosyasını Kontrol Et:**

   `models.py` dosyasını aç ve `MatchDataError` modelinin `match_id` alanının doğru bir şekilde tanımlandığından emin ol:

   ```python
   from django.db import models

   class MatchDataError(models.Model):
       match_id = models.IntegerField(verbose_name="Match ID", null=True, blank=True)  # match_id alanı doğru tanımlandı
       error_message = models.TextField(verbose_name="Error Message")
       timestamp = models.DateTimeField(auto_now_add=True, verbose_name="Timestamp")

       class Meta:
           verbose_name = "Match Data Error"
           verbose_name_plural = "Match Data Errors"

       def __str__(self):
           return f"Error for Match ID {self.match_id} at {self.timestamp}"
   ```

2. **Migration Oluşturma ve Veritabanına Uygulama:**

   Bu alan tanımlandıktan sonra `makemigrations` ve `migrate` komutlarını çalıştırarak değişikliklerin veritabanına yansımasını sağla:

   ```bash
   python manage.py makemigrations
   python manage.py migrate
   ```

### 2. Migration Dosyasında `match_id` Sütununun Tanımlandığından Emin Olma

Eğer hala aynı hatayı alıyorsan, `migrations` klasöründeki migration dosyasını kontrol et ve `match_id` sütununun ilgili migration dosyasında tanımlanmış olduğundan emin ol. Aşağıdaki adımları izleyebilirsin:

1. `migrations` klasörüne git ve en son oluşturulan migration dosyasını (`data.0004_alter_matchdataerror_options_and_more.py` gibi) aç.

2. Dosyada `match_id` alanının şu şekilde tanımlanmış olduğundan emin ol:

   ```python
   # Örnek migration dosyası
   class Migration(migrations.Migration):

       dependencies = [
           ('data', '0003_previous_migration_file'),  # Önceki migration dosyası
       ]

       operations = [
           migrations.AddField(
               model_name='matchdataerror',
               name='match_id',
               field=models.IntegerField(null=True, blank=True),
           ),
       ]
   ```

   Eğer bu tanım yoksa, `makemigrations` komutunu çalıştırarak `match_id` alanını migration dosyasına eklemeye çalış.

### 3. Veritabanında `match_id` Sütununun Olup Olmadığını Kontrol Et

Eğer yukarıdaki adımlar işe yaramazsa, veritabanına doğrudan bağlanarak `matchdataerror` tablosunda `match_id` sütununun olup olmadığını kontrol et.

1. **Veritabanı Bağlantısı ve Kontrol**:

   - PostgreSQL kullanıyorsan şu komutları kullanarak veritabanına bağlan:

     ```bash
     psql -U <kullanıcı_adı> -d <veritabanı_adı>
     ```

   - `matchdataerror` tablosunu kontrol et:

     ```sql
     \d data_matchdataerror;
     ```

     Bu komut tablo yapısını gösterecek ve `match_id` sütununun olup olmadığını kontrol etmeni sağlayacaktır.

2. Eğer `match_id` sütunu yoksa, manuel olarak bu sütunu ekleyebilirsin:

   ```sql
   ALTER TABLE data_matchdataerror ADD COLUMN match_id INTEGER;
   ```

3. Bu işlemden sonra Django migrate işlemlerini tekrar yap:

   ```bash
   python manage.py makemigrations
   python manage.py migrate
   ```

### 4. `migrate` ve `makemigrations` Sorunları İçin `--fake` Kullanma

Eğer `makemigrations` ve `migrate` işlemleri doğru çalışmıyor ve `match_id` sütunu veritabanında olmasına rağmen hata alıyorsan, `migrate` işlemini `--fake` seçeneği ile yaparak bu değişikliği geçerli saydırabilirsin:

```bash
python manage.py migrate --fake data
```

Bu komut, mevcut migration'ı veritabanı ile eşleştirir ve mevcut durumdaki farklılıkları yok sayar.

### 5. Mevcut `makemigrations` ve `migrate` Dosyalarını Temizleme

Eğer yukarıdaki adımlar işe yaramazsa ve veritabanı ile migration dosyaları arasında tutarsızlık varsa, `migrations` dosyalarını temizleyip (`__init__.py` hariç) yeniden oluşturmayı deneyebilirsin:

```bash
find . -path "*/migrations/*.py" -not -name "__init__.py" -delete
find . -path "*/migrations/*.pyc" -delete
```

Sonrasında:

```bash
python manage.py makemigrations
python manage.py migrate
```

Bu adımlar, `match_id` sütununu `MatchDataError` modeline doğru bir şekilde eklemene ve `ProgrammingError: column data_matchdataerror.match_id does not exist` hatasını çözmene yardımcı olacaktır. Eğer sorun devam ederse, veritabanı ve migration dosyalarının tam yapısını paylaşarak daha detaylı bir çözüm sunabilirim.

***Soru:*** return executor(sql, params, many, context)
           ^^^^^^^^^^^^^^^^^^^^^^^^^^^^^^^^^^^^
  File "/home/ahmety/Masaüstü/myenv/lib/python3.12/site-packages/django/db/backends/utils.py", line 100, in _execute
    with self.db.wrap_database_errors:
  File "/home/ahmety/Masaüstü/myenv/lib/python3.12/site-packages/django/db/utils.py", line 91, in __exit__
    raise dj_exc_value.with_traceback(traceback) from exc_value
  File "/home/ahmety/Masaüstü/myenv/lib/python3.12/site-packages/django/db/backends/utils.py", line 103, in _execute
    return self.cursor.execute(sql)
           ^^^^^^^^^^^^^^^^^^^^^^^^
django.db.utils.ProgrammingError: column "match_id" of relation "data_matchdataerror" does not exist

**Cevap:** Bu hata, Django veritabanında `data_matchdataerror` tablosunda `match_id` sütununun var olmadığını ve bu sütuna erişilmeye çalışıldığını belirtir. Bu genellikle `makemigrations` ve `migrate` işlemleri sırasında `match_id` sütununun veritabanına eklenmemiş olmasından kaynaklanır.

Hatanın nedeni ve çözümü için aşağıdaki adımları izleyebilirsin:

### 1. `makemigrations` ve `migrate` İşlemlerini Tekrar Yap

İlk olarak, `makemigrations` ve `migrate` komutlarını çalıştırarak `match_id` sütununu veritabanına ekleyip ekleyemeyeceğimizi kontrol edelim:

```bash
python manage.py makemigrations
python manage.py migrate
```

Eğer bu komutlar `No changes detected` gibi bir mesaj verirse, `match_id` sütunu migration dosyasına eklenmemiş demektir. Bu durumda, aşağıdaki adımları takip ederek sorunu çözebilirsin.

### 2. `MatchDataError` Modelini ve Migration Dosyasını Kontrol Et

1. **`models.py` Dosyasını Kontrol Et**:
   
   `MatchDataError` modelindeki `match_id` alanının doğru tanımlandığından emin ol:

   ```python
   from django.db import models

   class MatchDataError(models.Model):
       match_id = models.IntegerField(verbose_name="Match ID", null=True, blank=True)  # null=True ve blank=True ekleyin
       error_message = models.TextField(verbose_name="Error Message")
       timestamp = models.DateTimeField(auto_now_add=True, verbose_name="Timestamp")

       class Meta:
           verbose_name = "Match Data Error"
           verbose_name_plural = "Match Data Errors"

       def __str__(self):
           return f"Error for Match ID {self.match_id} at {self.timestamp}"
   ```

2. **Migration Dosyasını Kontrol Et**:
   
   `migrations` klasöründeki ilgili migration dosyasını kontrol et ve `match_id` alanının tanımlandığından emin ol:

   ```python
   class Migration(migrations.Migration):

       dependencies = [
           ('data', 'previous_migration_file'),  # Önceki migration dosyasını kontrol et
       ]

       operations = [
           migrations.AddField(
               model_name='matchdataerror',
               name='match_id',
               field=models.IntegerField(null=True, blank=True),
           ),
       ]
   ```

   Eğer `match_id` sütununun tanımlandığı bir migration dosyası yoksa, `makemigrations` komutunu çalıştır ve yeni bir migration dosyası oluştur:

   ```bash
   python manage.py makemigrations
   ```

3. **Migration Dosyasını Manuel Olarak Düzenleme**:

   Eğer `match_id` sütununun tanımlandığı migration dosyası varsa, ama veritabanında hala bu sütun bulunmuyorsa, migration dosyasını manuel olarak düzenleyebilirsin.

   `migrations` klasöründeki ilgili migration dosyasını aç ve `match_id` sütununu tanımlayan `AddField` satırını ekle:

   ```python
   migrations.AddField(
       model_name='matchdataerror',
       name='match_id',
       field=models.IntegerField(null=True, blank=True),
   ),
   ```

### 3. Mevcut `migrations` ve `migrate` Dosyalarını Temizleyip Yeniden Oluştur

Eğer `makemigrations` ve `migrate` işlemleri sorunu çözmezse, mevcut migration dosyalarında ve veritabanı şemasında tutarsızlıklar olabilir. Bu durumda `migrations` dosyalarını temizleyip yeniden oluşturmayı deneyebilirsin:

1. **`migrations` Dosyalarını Temizle**:

   ```bash
   find . -path "*/migrations/*.py" -not -name "__init__.py" -delete
   find . -path "*/migrations/*.pyc" -delete
   ```

   Bu komutlar `migrations` klasöründeki tüm migration dosyalarını silecektir (kök `__init__.py` dosyası hariç).

2. **Veritabanını Sıfırla (Opsiyonel)**:

   Eğer veritabanını sıfırlamak istiyorsan, tüm veritabanı verilerini silmek için `flush` komutunu kullanabilirsin:

   ```bash
   python manage.py flush
   ```

   Bu komut tüm veritabanı verilerini silecek ve veritabanını sıfırlayacaktır. Bu işlemi yapmadan önce verilerin yedeklendiğinden emin ol.

3. **Migration ve Migrate İşlemlerini Yeniden Yap**:

   `migrations` dosyalarını yeniden oluştur:

   ```bash
   python manage.py makemigrations
   python manage.py migrate
   ```

### 4. `match_id` Sütununu Manuel Olarak Veritabanına Eklemek

Eğer yukarıdaki adımlar işe yaramazsa, `match_id` sütununu manuel olarak veritabanına eklemeyi deneyebilirsin. Bunun için veritabanına bağlan ve `data_matchdataerror` tablosuna `match_id` sütununu ekle:

1. Veritabanına bağlan:

   ```bash
   psql -U <kullanıcı_adı> -d <veritabanı_adı>
   ```

2. `match_id` sütununu ekle:

   ```sql
   ALTER TABLE data_matchdataerror ADD COLUMN match_id INTEGER;
   ```

3. Bu işlemi yaptıktan sonra tekrar `migrate` komutunu çalıştır:

   ```bash
   python manage.py migrate
   ```

### 5. `--fake` Seçeneği ile Migrate İşlemini Zorla

Eğer `migrate` işlemi sırasında `match_id` sütununun zaten var olduğunu söylüyor ve aynı hatayı almaya devam ediyorsan, `--fake` seçeneği ile migrate işlemini zorla:

```bash
python manage.py migrate --fake data
```

Bu komut, mevcut migration'ı veritabanı ile eşleştirir ve veritabanı değişikliklerini zorlar.

### 6. Veritabanını ve Django ORM'yi Senkronize Et

Eğer `data_matchdataerror` tablosu ile ilgili `ProgrammingError` hatası devam ederse, veritabanı ve Django ORM arasında senkronizasyon sorunu olabilir. Bu durumda veritabanındaki `data_matchdataerror` tablosunu ve Django'daki `models.py` dosyasını senkronize ettiğinden emin ol:

- `match_id` alanını `models.py` dosyasından ve veritabanından manuel olarak kaldır, ardından tekrar `makemigrations` ve `migrate` yap.

Bu adımlar `match_id` sütununu `MatchDataError` modeline eklemeye ve `ProgrammingError: column data_matchdataerror.match_id does not exist` hatasını çözmeye yardımcı olacaktır. Eğer hala sorun yaşıyorsan, daha fazla detay ve veritabanı yapısını paylaşarak destek alabilirim.

***Soru:*** from django.db import models
from django.utils import timezone
class Match(models.Model):
    # Temel Bilgiler
    Tarih = models.DateField()  
    customId = models.CharField(max_length=10)  
    id = models.BigIntegerField(primary_key=True)
    startTimestamp = models.DateTimeField(default=timezone.now, null=True, blank=True)  # Geçerli bir varsayılan datetime değeri atandı.
    
    # Turnuva Bilgileri
    tournament_name = models.CharField(max_length=255)
    tournament_category_name = models.CharField(max_length=255)
    season_name = models.CharField(max_length=50)
    season_year = models.CharField(max_length=50)
    tournament_uniqueTournament_id = models.IntegerField()
    season_id = models.IntegerField()
    roundInfo_round = models.IntegerField(blank=True, null=True, default=0)    
    # Maç Durumu
    status_type = models.CharField(max_length=50)
    
    # Ev Sahibi Takım Bilgileri
    homeTeam_name = models.CharField(max_length=255)
    homeTeam_nameCode = models.CharField(max_length=10)
    homeTeam_id = models.IntegerField()
    
    # Deplasman Takımı Bilgileri
    awayTeam_name = models.CharField(max_length=255)
    awayTeam_nameCode = models.CharField(max_length=10)
    awayTeam_id = models.IntegerField()
    
    # Ev Sahibi Skor Bilgileri
    homeScore_normaltime = models.FloatField(default=0, blank=True, null=True)  
    homeScore_period1 = models.FloatField(default=0, blank=True, null=True)
    homeScore_period2 = models.FloatField(default=0, blank=True, null=True)

    # Deplasman Skor Bilgileri
    awayScore_normaltime = models.FloatField(default=0, blank=True, null=True)
    awayScore_period1 = models.FloatField(default=0, blank=True, null=True)
    awayScore_period2 = models.FloatField(default=0, blank=True, null=True)

    class Meta:
        verbose_name = 'Maç'
        verbose_name_plural = 'Maçlar'

    def __str__(self):
        return f"{self.tournament_name} - {self.homeTeam_name} vs {self.awayTeam_name}"


class ErrorLog(models.Model):
    """Hata durumlarını kayıt altına almak için kullanılan model."""
    error_type = models.CharField(max_length=255)  # Hata türü (API hatası, veri işleme hatası vb.)
    error_message = models.TextField()  # Hata mesajı
    date = models.DateField()  # Hata oluşan tarih
    match_id = models.CharField(max_length=255, blank=True, null=True)  # Hata oluşan maç ID'si (varsa)
    response_code = models.IntegerField(blank=True, null=True)  # HTTP yanıt kodu (örn: 200, 404)
    response_message = models.TextField(blank=True, null=True)  # HTTP yanıt mesajı
    created_at = models.DateTimeField(auto_now_add=True)  # Hata oluşma zamanı

    def __str__(self):
        return f"{self.date} - {self.error_type}"




    class ExpectedGoals(models.Model):
        match = models.ForeignKey(Match, on_delete=models.CASCADE, related_name='expected_goals', verbose_name="Match")
        home = models.FloatField(verbose_name="Home Expected Goals")
        away = models.FloatField(verbose_name="Away Expected Goals")
        compare_code = models.PositiveSmallIntegerField(verbose_name="Compare Code")
        statistics_type = models.CharField(max_length=50, verbose_name="Statistics Type")
        value_type = models.CharField(max_length=50, verbose_name="Value Type")
        home_value = models.FloatField(verbose_name="Home Value")
        away_value = models.FloatField(verbose_name="Away Value")
        render_type = models.PositiveSmallIntegerField(verbose_name="Render Type")
        key = models.CharField(max_length=50, verbose_name="Key")
        period = models.CharField(max_length=20, verbose_name="Period")
        group_name = models.CharField(max_length=50, verbose_name="Group Name")
        home_total = models.FloatField(null=True, blank=True, verbose_name="Home Total")
        away_total = models.FloatField(null=True, blank=True, verbose_name="Away Total")

    class Meta:
        verbose_name = "Expected Goals"
        verbose_name_plural = "Expected Goals"

    def __str__(self):
        return f"Match {self.match.id} - Expected Goals: Home {self.home} vs Away {self.away}"

from django.db import models


class MatchDataError(models.Model):
    match_id = models.IntegerField(verbose_name="Match ID", null=True, blank=True)  # null=True ve blank=True ekleyin
    error_message = models.TextField(verbose_name="Error Message")
    timestamp = models.DateTimeField(auto_now_add=True, verbose_name="Timestamp")

    class Meta:
        verbose_name = "Match Data Error"
        verbose_name_plural = "Match Data Errors"

    def __str__(self):
        return f"Error for Match ID {self.match_id} at {self.timestamp}"


    class Meta:
        verbose_name = "Match Data Error"
        verbose_name_plural = "Match Data Errors"

    def __str__(self):
        return f"Error for Match ID {self.match_id} at {self.timestamp}"  modelim bunalr şlimdi tammen bunalrı düzeltsene ve kodları tam olarak yaz

**Cevap:** Elbette, modellerinde bazı düzenlemeler yaparak daha temiz ve sorunsuz bir yapı oluşturabiliriz. Kod yapısında iç içe sınıf tanımları (nested classes) ve format hataları olduğu için bu yapıyı daha anlaşılır hale getirip düzeltiyorum. Ayrıca `Meta` sınıfları ve `__str__` fonksiyonlarını da doğru konumlara yerleştiriyorum.

Aşağıda tüm modellerin düzeltilmiş hali yer almakta:

```python
from django.db import models
from django.utils import timezone


# Match Modeli
class Match(models.Model):
    # Temel Bilgiler
    Tarih = models.DateField()  
    customId = models.CharField(max_length=10)  
    id = models.BigIntegerField(primary_key=True)
    startTimestamp = models.DateTimeField(default=timezone.now, null=True, blank=True)  # Geçerli bir varsayılan datetime değeri atandı.

    # Turnuva Bilgileri
    tournament_name = models.CharField(max_length=255)
    tournament_category_name = models.CharField(max_length=255)
    season_name = models.CharField(max_length=50)
    season_year = models.CharField(max_length=50)
    tournament_uniqueTournament_id = models.IntegerField()
    season_id = models.IntegerField()
    roundInfo_round = models.IntegerField(blank=True, null=True, default=0)

    # Maç Durumu
    status_type = models.CharField(max_length=50)

    # Ev Sahibi Takım Bilgileri
    homeTeam_name = models.CharField(max_length=255)
    homeTeam_nameCode = models.CharField(max_length=10)
    homeTeam_id = models.IntegerField()

    # Deplasman Takımı Bilgileri
    awayTeam_name = models.CharField(max_length=255)
    awayTeam_nameCode = models.CharField(max_length=10)
    awayTeam_id = models.IntegerField()

    # Ev Sahibi Skor Bilgileri
    homeScore_normaltime = models.FloatField(default=0, blank=True, null=True)
    homeScore_period1 = models.FloatField(default=0, blank=True, null=True)
    homeScore_period2 = models.FloatField(default=0, blank=True, null=True)

    # Deplasman Skor Bilgileri
    awayScore_normaltime = models.FloatField(default=0, blank=True, null=True)
    awayScore_period1 = models.FloatField(default=0, blank=True, null=True)
    awayScore_period2 = models.FloatField(default=0, blank=True, null=True)

    class Meta:
        verbose_name = 'Maç'
        verbose_name_plural = 'Maçlar'

    def __str__(self):
        return f"{self.tournament_name} - {self.homeTeam_name} vs {self.awayTeam_name}"


# ExpectedGoals Modeli
class ExpectedGoals(models.Model):
    match = models.ForeignKey(Match, on_delete=models.CASCADE, related_name='expected_goals', verbose_name="Match")
    home = models.FloatField(verbose_name="Home Expected Goals")
    away = models.FloatField(verbose_name="Away Expected Goals")
    compare_code = models.PositiveSmallIntegerField(verbose_name="Compare Code")
    statistics_type = models.CharField(max_length=50, verbose_name="Statistics Type")
    value_type = models.CharField(max_length=50, verbose_name="Value Type")
    home_value = models.FloatField(verbose_name="Home Value")
    away_value = models.FloatField(verbose_name="Away Value")
    render_type = models.PositiveSmallIntegerField(verbose_name="Render Type")
    key = models.CharField(max_length=50, verbose_name="Key")
    period = models.CharField(max_length=20, verbose_name="Period")
    group_name = models.CharField(max_length=50, verbose_name="Group Name")
    home_total = models.FloatField(null=True, blank=True, verbose_name="Home Total")
    away_total = models.FloatField(null=True, blank=True, verbose_name="Away Total")

    class Meta:
        verbose_name = "Expected Goals"
        verbose_name_plural = "Expected Goals"

    def __str__(self):
        return f"Match {self.match.id} - Expected Goals: Home {self.home} vs Away {self.away}"


# ErrorLog Modeli (Hata kayıtları için)
class ErrorLog(models.Model):
    error_type = models.CharField(max_length=255)  # Hata türü (API hatası, veri işleme hatası vb.)
    error_message = models.TextField()  # Hata mesajı
    date = models.DateField()  # Hata oluşan tarih
    match_id = models.CharField(max_length=255, blank=True, null=True)  # Hata oluşan maç ID'si (varsa)
    response_code = models.IntegerField(blank=True, null=True)  # HTTP yanıt kodu (örn: 200, 404)
    response_message = models.TextField(blank=True, null=True)  # HTTP yanıt mesajı
    created_at = models.DateTimeField(auto_now_add=True)  # Hata oluşma zamanı

    class Meta:
        verbose_name = "Error Log"
        verbose_name_plural = "Error Logs"

    def __str__(self):
        return f"{self.date} - {self.error_type}"


# MatchDataError Modeli (Maç verisi hataları için)
class MatchDataError(models.Model):
    match_id = models.IntegerField(verbose_name="Match ID", null=True, blank=True)
    error_message = models.TextField(verbose_name="Error Message")
    timestamp = models.DateTimeField(auto_now_add=True, verbose_name="Timestamp")

    class Meta:
        verbose_name = "Match Data Error"
        verbose_name_plural = "Match Data Errors"

    def __str__(self):
        return f"Error for Match ID {self.match_id} at {self.timestamp}"
```

### Düzenlemeler:
1. **`Match` Modeli**: `Match` modelinin `__str__` fonksiyonu ve `Meta` sınıfı düzenlendi.
2. **`ExpectedGoals` Modeli**: `ExpectedGoals` modelinin iç yapısı ve `Meta` sınıfı doğru şekilde düzenlendi ve `__str__` fonksiyonu doğru konuma getirildi.
3. **`ErrorLog` Modeli**: `ErrorLog` modeli bağımsız hale getirildi ve `Meta` sınıfı eklendi.
4. **`MatchDataError` Modeli**: `MatchDataError` modelindeki `Meta` sınıfı ve `__str__` fonksiyonu doğru konuma yerleştirildi ve `match_id` alanı tanımlandı.

Bu düzenlemeler sonrasında `makemigrations` ve `migrate` işlemlerini tekrar yaparak veritabanı değişikliklerini uygulayabilirsin:

```bash
python manage.py makemigrations
python manage.py migrate
```

Eğer hala herhangi bir sorun yaşarsan, lütfen hata mesajını ve ilgili durumu tekrar paylaş, daha detaylı inceleyebilirim!

***Soru:*** Traceback (most recent call last):
  File "/home/ahmety/Masaüstü/DjangoPro/data/tasks.py", line 493, in fetch_match_statistics
    match = Match.objects.get(id=match_id)
            ^^^^^^^^^^^^^^^^^^^^^^^^^^^^^^
  File "/home/ahmety/Masaüstü/myenv/lib/python3.12/site-packages/django/db/models/manager.py", line 87, in manager_method
    return getattr(self.get_queryset(), name)(*args, **kwargs)
           ^^^^^^^^^^^^^^^^^^^^^^^^^^^^^^^^^^^^^^^^^^^^^^^^^^^
  File "/home/ahmety/Masaüstü/myenv/lib/python3.12/site-packages/django/db/models/query.py", line 649, in get
    raise self.model.DoesNotExist(
data.models.Match.DoesNotExist: Match matching query does not exist.

During handling of the above exception, another exception occurred:

Traceback (most recent call last):
  File "/home/ahmety/Masaüstü/myenv/lib/python3.12/site-packages/django/db/backends/utils.py", line 105, in _execute
    return self.cursor.execute(sql, params)
           ^^^^^^^^^^^^^^^^^^^^^^^^^^^^^^^^
psycopg2.errors.UndefinedColumn: column "match_id" of relation "data_matchdataerror" does not exist
LINE 1: INSERT INTO "data_matchdataerror" ("match_id", "error_messag...
                                           ^


The above exception was the direct cause of the following exception:

Traceback (most recent call last):
  File "/home/ahmety/Masaüstü/myenv/lib/python3.12/site-packages/celery/app/trace.py", line 453, in trace_task
    R = retval = fun(*args, **kwargs)
                 ^^^^^^^^^^^^^^^^^^^^
  File "/home/ahmety/Masaüstü/myenv/lib/python3.12/site-packages/celery/app/trace.py", line 736, in __protected_call__
    return self.run(*args, **kwargs)
           ^^^^^^^^^^^^^^^^^^^^^^^^^
  File "/home/ahmety/Masaüstü/DjangoPro/data/tasks.py", line 514, in fetch_match_statistics
    MatchDataError.objects.create(match_id=match_id, error_message=f"Match with ID {match_id} does not exist.")
  File "/home/ahmety/Masaüstü/myenv/lib/python3.12/site-packages/django/db/models/manager.py", line 87, in manager_method
    return getattr(self.get_queryset(), name)(*args, **kwargs)
           ^^^^^^^^^^^^^^^^^^^^^^^^^^^^^^^^^^^^^^^^^^^^^^^^^^^
  File "/home/ahmety/Masaüstü/myenv/lib/python3.12/site-packages/django/db/models/query.py", line 679, in create
    obj.save(force_insert=True, using=self.db)
  File "/home/ahmety/Masaüstü/myenv/lib/python3.12/site-packages/django/db/models/base.py", line 891, in save
    self.save_base(
  File "/home/ahmety/Masaüstü/myenv/lib/python3.12/site-packages/django/db/models/base.py", line 997, in save_base
    updated = self._save_table(
              ^^^^^^^^^^^^^^^^^
  File "/home/ahmety/Masaüstü/myenv/lib/python3.12/site-packages/django/db/models/base.py", line 1160, in _save_table
    results = self._do_insert(
              ^^^^^^^^^^^^^^^^
  File "/home/ahmety/Masaüstü/myenv/lib/python3.12/site-packages/django/db/models/base.py", line 1201, in _do_insert
    return manager._insert(
           ^^^^^^^^^^^^^^^^
  File "/home/ahmety/Masaüstü/myenv/lib/python3.12/site-packages/django/db/models/manager.py", line 87, in manager_method
    return getattr(self.get_queryset(), name)(*args, **kwargs)
           ^^^^^^^^^^^^^^^^^^^^^^^^^^^^^^^^^^^^^^^^^^^^^^^^^^^
  File "/home/ahmety/Masaüstü/myenv/lib/python3.12/site-packages/django/db/models/query.py", line 1847, in _insert
    return query.get_compiler(using=using).execute_sql(returning_fields)
           ^^^^^^^^^^^^^^^^^^^^^^^^^^^^^^^^^^^^^^^^^^^^^^^^^^^^^^^^^^^^^
  File "/home/ahmety/Masaüstü/myenv/lib/python3.12/site-packages/django/db/models/sql/compiler.py", line 1836, in execute_sql
    cursor.execute(sql, params)
  File "/home/ahmety/Masaüstü/myenv/lib/python3.12/site-packages/django/db/backends/utils.py", line 122, in execute
    return super().execute(sql, params)
           ^^^^^^^^^^^^^^^^^^^^^^^^^^^^
  File "/home/ahmety/Masaüstü/myenv/lib/python3.12/site-packages/django/db/backends/utils.py", line 79, in execute
    return self._execute_with_wrappers(
           ^^^^^^^^^^^^^^^^^^^^^^^^^^^^
  File "/home/ahmety/Masaüstü/myenv/lib/python3.12/site-packages/django/db/backends/utils.py", line 92, in _execute_with_wrappers
    return executor(sql, params, many, context)
           ^^^^^^^^^^^^^^^^^^^^^^^^^^^^^^^^^^^^
  File "/home/ahmety/Masaüstü/myenv/lib/python3.12/site-packages/django/db/backends/utils.py", line 100, in _execute
    with self.db.wrap_database_errors:
  File "/home/ahmety/Masaüstü/myenv/lib/python3.12/site-packages/django/db/utils.py", line 91, in __exit__
    raise dj_exc_value.with_traceback(traceback) from exc_value
  File "/home/ahmety/Masaüstü/myenv/lib/python3.12/site-packages/django/db/backends/utils.py", line 105, in _execute
    return self.cursor.execute(sql, params)
           ^^^^^^^^^^^^^^^^^^^^^^^^^^^^^^^^
django.db.utils.ProgrammingError: column "match_id" of relation "data_matchdataerror" does not exist
LINE 1: INSERT INTO "data_matchdataerror" ("match_id", "error_messag...
                                           ^  bu hatayı neden hala alıyoruz biraz dikkat eder misin

**Cevap:** Bu hata, `data_matchdataerror` tablosunda `match_id` sütununun veritabanında hala var olmadığını gösteriyor. Hata mesajına göre, `MatchDataError` modeli `match_id` alanını eklemeye çalışırken veritabanında bu sütun mevcut olmadığı için `ProgrammingError` hatası alıyorsun.

Bu hatayı gidermek için aşağıdaki adımları dikkatle takip edebilirsin:

### 1. **Mevcut Veritabanı Şemasını Kontrol Et**

İlk olarak, veritabanındaki `data_matchdataerror` tablosunu kontrol ederek `match_id` sütununun olup olmadığını kesin olarak öğrenmeliyiz.

1. **Veritabanına Bağlan**:
   
   Eğer PostgreSQL kullanıyorsan, terminalde aşağıdaki komut ile veritabanına bağlan:

   ```bash
   psql -U <kullanıcı_adı> -d <veritabanı_adı>
   ```

2. **`data_matchdataerror` Tablosunun Yapısını Kontrol Et**:

   Veritabanına bağlandıktan sonra `data_matchdataerror` tablosunun yapısını kontrol et:

   ```sql
   \d data_matchdataerror;
   ```

   Bu komut tablo yapısını gösterecek ve `match_id` sütununun olup olmadığını görmemizi sağlayacak.

   - Eğer `match_id` sütunu yoksa, bir sonraki adımdaki `migrate` işlemlerini yaparak bu sütunu ekleyelim.
   - Eğer `match_id` sütunu varsa, `makem

***Soru:*** lütfren veri tabanını kontrol etme sadece düzelt

**Cevap:** Tamam, veritabanına müdahale etmeden ve `models.py` dosyasındaki düzenlemeleri göz önünde bulundurarak hatayı düzelteceğiz. Mevcut hatanın çözümü için aşağıdaki adımları dikkatlice uygula.

### Sorunun Kaynağı ve Çözümü

Hata, `MatchDataError` modeline `match_id` alanının veritabanına düzgün bir şekilde eklenmemiş olmasından kaynaklanıyor. `makemigrations` ve `migrate` işlemleri sırasında bu alanın veritabanına eklenmediği durumda, modelde tanımlı olmasına rağmen veritabanında bulunamıyor. Bu durumu çözmek için `models.py` dosyasındaki hataları kontrol edip, migration işlemlerini tekrar yapmamız gerekiyor.

### Adım 1: `models.py` Dosyasını Düzenle

Öncelikle `models.py` dosyasındaki `MatchDataError` modelini düzenleyelim ve herhangi bir fazlalık veya hatalı `Meta` sınıfını temizleyelim. Kodun güncel halini aşağıda bulabilirsin:

```python
from django.db import models
from django.utils import timezone

# Match Modeli
class Match(models.Model):
    Tarih = models.DateField()
    customId = models.CharField(max_length=10)
    id = models.BigIntegerField(primary_key=True)
    startTimestamp = models.DateTimeField(default=timezone.now, null=True, blank=True)

    # Turnuva Bilgileri
    tournament_name = models.CharField(max_length=255)
    tournament_category_name = models.CharField(max_length=255)
    season_name = models.CharField(max_length=50)
    season_year = models.CharField(max_length=50)
    tournament_uniqueTournament_id = models.IntegerField()
    season_id = models.IntegerField()
    roundInfo_round = models.IntegerField(blank=True, null=True, default=0)

    # Maç Durumu
    status_type = models.CharField(max_length=50)

    # Ev Sahibi Takım Bilgileri
    homeTeam_name = models.CharField(max_length=255)
    homeTeam_nameCode = models.CharField(max_length=10)
    homeTeam_id = models.IntegerField()

    # Deplasman Takımı Bilgileri
    awayTeam_name = models.CharField(max_length=255)
    awayTeam_nameCode = models.CharField(max_length=10)
    awayTeam_id = models.IntegerField()

    # Ev Sahibi Skor Bilgileri
    homeScore_normaltime = models.FloatField(default=0, blank=True, null=True)
    homeScore_period1 = models.FloatField(default=0, blank=True, null=True)
    homeScore_period2 = models.FloatField(default=0, blank=True, null=True)

    # Deplasman Skor Bilgileri
    awayScore_normaltime = models.FloatField(default=0, blank=True, null=True)
    awayScore_period1 = models.FloatField(default=0, blank=True, null=True)
    awayScore_period2 = models.FloatField(default=0, blank=True, null=True)

    class Meta:
        verbose_name = 'Maç'
        verbose_name_plural = 'Maçlar'

    def __str__(self):
        return f"{self.tournament_name} - {self.homeTeam_name} vs {self.awayTeam_name}"


# ExpectedGoals Modeli
class ExpectedGoals(models.Model):
    match = models.ForeignKey(Match, on_delete=models.CASCADE, related_name='expected_goals', verbose_name="Match")
    home = models.FloatField(verbose_name="Home Expected Goals")
    away = models.FloatField(verbose_name="Away Expected Goals")
    compare_code = models.PositiveSmallIntegerField(verbose_name="Compare Code")
    statistics_type = models.CharField(max_length=50, verbose_name="Statistics Type")
    value_type = models.CharField(max_length=50, verbose_name="Value Type")
    home_value = models.FloatField(verbose_name="Home Value")
    away_value = models.FloatField(verbose_name="Away Value")
    render_type = models.PositiveSmallIntegerField(verbose_name="Render Type")
    key = models.CharField(max_length=50, verbose_name="Key")
    period = models.CharField(max_length=20, verbose_name="Period")
    group_name = models.CharField(max_length=50, verbose_name="Group Name")
    home_total = models.FloatField(null=True, blank=True, verbose_name="Home Total")
    away_total = models.FloatField(null=True, blank=True, verbose_name="Away Total")

    class Meta:
        verbose_name = "Expected Goals"
        verbose_name_plural = "Expected Goals"

    def __str__(self):
        return f"Match {self.match.id} - Expected Goals: Home {self.home} vs Away {self.away}"


# ErrorLog Modeli
class ErrorLog(models.Model):
    error_type = models.CharField(max_length=255)
    error_message = models.TextField()
    date = models.DateField()
    match_id = models.CharField(max_length=255, blank=True, null=True)
    response_code = models.IntegerField(blank=True, null=True)
    response_message = models.TextField(blank=True, null=True)
    created_at = models.DateTimeField(auto_now_add=True)

    class Meta:
        verbose_name = "Error Log"
        verbose_name_plural = "Error Logs"

    def __str__(self):
        return f"{self.date} - {self.error_type}"


# MatchDataError Modeli
class MatchDataError(models.Model):
    match_id = models.IntegerField(verbose_name="Match ID", null=True, blank=True)
    error_message = models.TextField(verbose_name="Error Message")
    timestamp = models.DateTimeField(auto_now_add=True, verbose_name="Timestamp")

    class Meta:
        verbose_name = "Match Data Error"
        verbose_name_plural = "Match Data Errors"

    def __str__(self):
        return f"Error for Match ID {self.match_id} at {self.timestamp}"
```

Bu düzenlemeyle birlikte `models.py` dosyasındaki `Meta` ve `__str__` fonksiyonları doğru konumlarda ve `MatchDataError` modelinde `match_id` alanı tanımlı durumda.

### Adım 2: `makemigrations` ve `migrate` İşlemlerini Yapma

Bu düzenlemelerden sonra migration dosyasını yeniden oluşturup veritabanına uygulayalım:

1. **`makemigrations` Komutunu Çalıştır**:

   ```bash
   python manage.py makemigrations
   ```

   Bu komut, `models.py` dosyasındaki değişikliklere göre yeni bir migration dosyası oluşturacaktır. Eğer herhangi bir hata veya uyarı görmezsen, bir sonraki adıma geçebilirsin.

2. **`migrate` Komutunu Çalıştır**:

   ```bash
   python manage.py migrate
   ```

   Bu komut, oluşturulan migration dosyasını veritabanına uygulayacak ve `match_id` sütunu `data_matchdataerror` tablosuna eklenecektir.

### Adım 3: Celery Görevi Sırasında Hataların Güncellenmesi

`fetch_match_statistics` fonksiyonunda `Match` modeline uygun `match_id` bulunamadığı durumlarda `MatchDataError` kaydını yaparken `match_id` parametresini doğru şekilde aldığından emin ol. Ayrıca `Match` veritabanında `match_id`'ye karşılık gelen bir kayıt olup olmadığını kontrol et.

```python
from .models import Match, MatchDataError

def fetch_match_statistics(match_id):
    try:
        match = Match.objects.get(id=match_id)
        # Match ile ilgili işlemler burada yapılacak
    except Match.DoesNotExist:
        # Match bulunamadığında MatchDataError kaydı yap
        MatchDataError.objects.create(match_id=match_id, error_message=f"Match with ID {match_id} does not exist.")
```

Bu adımları ve düzenlemeleri yaptıktan sonra `match_id` alanı `MatchDataError` tablosuna eklenmiş olacak ve `data_matchdataerror` tablosunda `match_id` sütunu bulunacaktır. Eğer hala hata alırsan, ilgili `makemigrations` ve `migrate` işlemlerinden alınan çıktıyı veya oluşan hatayı paylaşabilirsin.

***Soru:*** tamamen veritabanlarını silip tekrar oluşturalım 0 dan

**Cevap:** Veritabanını tamamen silip yeniden oluşturmak, veritabanındaki tüm tabloları ve verileri sıfırlayacaktır. Bu işlemi yaparken, mevcut veritabanı yedeğiniz yoksa tüm verilerinizin kaybolacağını unutmayın. Bu işlemi dikkatlice ve yalnızca gerekliyse yapmanızı öneririm.

Aşağıda veritabanınızı tamamen sıfırlayıp tekrar oluşturmanız için gerekli adımları bulabilirsiniz:

### Adım 1: Mevcut Veritabanını Silme

1. **Veritabanını Silme (`dropdb`)**:
   Veritabanını silmek için terminalden aşağıdaki komutu çalıştırabilirsiniz:

   **PostgreSQL için**:

   ```bash
   dropdb <veritabanı_adı> -U <kullanıcı_adı>
   ```

   Eğer `dropdb` komutunu kullanamıyorsanız, PostgreSQL terminaline girip veritabanını manuel olarak da silebilirsiniz:

   ```bash
   psql -U <kullanıcı_adı>
   ```

   Ardından PostgreSQL terminaline girdikten sonra:

   ```sql
   DROP DATABASE <veritabanı_adı>;
   ```

   **SQLite için**:
   Eğer SQLite kullanıyorsanız, veritabanı dosyasını silmeniz yeterlidir:

   ```bash
   rm -rf db.sqlite3
   ```

2. **Mevcut `migrations` Dosyalarını Temizleme**:
   Django projende, tüm `migrations` dosyalarını temizlemek için aşağıdaki komutları kullanabilirsiniz:

   ```bash
   find . -path "*/migrations/*.py" -not -name "__init__.py" -delete
   find . -path "*/migrations/*.pyc" -delete
   ```

   Bu komutlar tüm `migrations` dosyalarını siler ve sadece `__init__.py` dosyasını bırakır. Bu sayede veritabanını sıfırdan oluşturabiliriz.

### Adım 2: Yeni Veritabanı Oluşturma

1. **Veritabanını Oluşturma**:

   **PostgreSQL için**:
   
   Eğer veritabanını sildiyseniz, yeniden oluşturmak için şu komutu kullanabilirsiniz:

   ```bash
   createdb <veritabanı_adı> -U <kullanıcı_adı>
   ```

   Alternatif olarak PostgreSQL terminaline bağlanarak da veritabanını oluşturabilirsiniz:

   ```bash
   psql -U <kullanıcı_adı>
   CREATE DATABASE <veritabanı_adı>;
   ```

   **SQLite için**:
   Eğer SQLite kullanıyorsanız, `migrate` işlemi veritabanını otomatik olarak oluşturacaktır.

### Adım 3: Yeni Migration Dosyaları Oluşturma ve Veritabanına Uygulama

1. **Migration Dosyalarını Oluşturma**:
   
   `models.py` dosyasında tüm tabloları ve yapıları tanımladıktan sonra, yeni migration dosyaları oluşturmak için şu komutu çalıştırın:

   ```bash
   python manage.py makemigrations
   ```

   Bu komut tüm modeller için yeni `migrations` dosyalarını oluşturacaktır.

2. **Migration Dosyalarını Veritabanına Uygulama**:
   
   Yeni oluşturulan migration dosyalarını veritabanına uygulamak için aşağıdaki komutu çalıştırın:

   ```bash
   python manage.py migrate
   ```

   Bu komut veritabanında tüm tabloları ve yapıları sıfırdan oluşturacaktır.

### Adım 4: Süper Kullanıcı Oluşturma ve Test Etme

Yeni veritabanını oluşturduktan sonra, admin paneline giriş yapabilmek için süper kullanıcı oluşturmanız gerekecek:

```bash
python manage.py createsuperuser
```

Bu komut ile bir süper kullanıcı oluşturun ve giriş bilgilerinizi belirleyin.

### Adım 5: Projeyi Başlatma ve Kontrol Etme

Son olarak projeyi başlatıp her şeyin doğru çalıştığını kontrol edin:

```bash
python manage.py runserver
```

Bu adımlar veritabanını tamamen sıfırlayıp tekrar oluşturmanıza yardımcı olacaktır. Eğer başka bir sorunla karşılaşırsanız, lütfen detaylı hata mesajını ve yaşadığınız durumu tekrar paylaşın!

***Soru:*** for _, row in all_data.iterrows():
            ExpectedGoals.objects.create(
              
                home=row.get('home', 0),
                away=row.get('away', 0),
                compare_code=row.get('compareCode', 0),
                statistics_type=row.get('statisticsType', ''),
                value_type=row.get('valueType', ''),
                home_value=row.get('homeValue', 0),
                away_value=row.get('awayValue', 0),
                render_type=row.get('renderType', 0),
                key=row.get('key', ''),
                period=row.get('period', 'ALL'),
                group_name=row.get('groupName', ''),
                home_total=row.get('homeTotal', None),
                away_total=row.get('awayTotal', None)verielri alırken     match=row['match'], bu şekilde yaz hepsini
            )

**Cevap:** Eğer `ExpectedGoals` modeline verileri eklerken `match` alanını da `row` verilerinden almak istiyorsan ve `match` modeline `ForeignKey` olarak tanımlanmışsa, `match` alanını `ExpectedGoals` tablosuna eklerken `Match` modelinden ilgili `match_id`'yi almanız gerekir.

Örneğin, `match` alanı `ExpectedGoals` modelinde `ForeignKey` olarak `Match` modeline tanımlandığında, `match_id`'yi `row` verisinden alıp `Match` modelinden uygun kaydı seçmeniz gerekecektir.

Aşağıda, `ExpectedGoals` modeline `match` alanını ekleyip, `for` döngüsünde `match` parametresini alarak `ExpectedGoals` tablosuna eklemenin nasıl yapıldığını gösteriyorum:

```python
from .models import ExpectedGoals, Match  # Modellerinizi içe aktarın

# Verileri ExpectedGoals modeline eklemek için for döngüsü
for _, row in all_data.iterrows():
    try:
        # `match_id`'yi `row` verisinden al
        match_id = row.get('match_id', None)  # 'match_id' sütununu aldığınızdan emin olun
        if match_id:
            # `Match` modelinde `match_id`'ye sahip kaydı al
            match = Match.objects.get(id=match_id)

            # ExpectedGoals kaydını oluştur
            ExpectedGoals.objects.create(
                match=match,  # `match` alanını `Match` modelinden gelen kayda bağla
                home=row.get('home', 0),
                away=row.get('away', 0),
                compare_code=row.get('compareCode', 0),
                statistics_type=row.get('statisticsType', ''),
                value_type=row.get('valueType', ''),
                home_value=row.get('homeValue', 0),
                away_value=row.get('awayValue', 0),
                render_type=row.get('renderType', 0),
                key=row.get('key', ''),
                period=row.get('period', 'ALL'),
                group_name=row.get('groupName', ''),
                home_total=row.get('homeTotal', None),
                away_total=row.get('awayTotal', None)
            )
    except Match.DoesNotExist:
        print(f"Match with ID {match_id} does not exist in the Match table.")
```

### Önemli Noktalar:
1. **`Match` Modelinden `match_id` İle Kayıt Alma**:
   - `row` verilerinizde `match_id` isimli bir sütun olmalı.
   - `match_id` değerini alıp, `Match` modelinde bu `id`'ye sahip bir kayıt olup olmadığını kontrol ediyoruz.
   - Eğer `Match` tablosunda bu `id`'ye sahip bir kayıt yoksa `Match.DoesNotExist` hatası alırsınız. Bu durumda, bir hata mesajı yazdırabilir veya hata kaydını tutabilirsiniz.

2. **`match` Alanını `ForeignKey` Olarak Tanımlayın**:
   - `ExpectedGoals` modelinde `match` alanı `ForeignKey` olarak `Match` modeline bağlı olmalıdır:

   ```python
   class ExpectedGoals(models.Model):
       match = models.ForeignKey(Match, on_delete=models.CASCADE, related_name='expected_goals', verbose_name="Match")
       home = models.FloatField(verbose_name="Home Expected Goals")
       away = models.FloatField(verbose_name="Away Expected Goals")
       # Diğer alanlar...
   ```

3. **Verilerin `Match` Tablosunda Olup Olmadığını Kontrol Edin**:
   - Eğer `row` verilerinizde `match_id` değeri `Match` tablosunda yoksa, `Match.DoesNotExist` hatası alınacaktır. Bu durumda veritabanında `Match` verilerinin doğru eklenip eklenmediğini kontrol edin.

### Alternatif Çözüm: `get_or_create` Kullanma
Eğer `Match` tablosunda `match_id`'ye sahip kayıtların olup olmadığını sürekli kontrol etmek istemiyorsanız, `get_or_create` yöntemini kullanabilirsiniz. Bu yöntem, `match_id`'ye sahip bir `Match` kaydı yoksa yeni bir `Match` oluşturacak, varsa mevcut kaydı kullanacaktır.

```python
for _, row in all_data.iterrows():
    match_id = row.get('match_id', None)
    if match_id:
        # `Match` modelinde `match_id`'yi kontrol edip, yoksa oluşturur
        match, created = Match.objects.get_or_create(
            id=match_id,
            defaults={
                'Tarih': row.get('Tarih', timezone.now().date()),  # Varsayılan bir tarih değeri atayın
                'customId': row.get('customId', 'default'),  # Varsayılan customId değerini ayarlayın
                # Diğer alanları ekleyebilirsiniz...
            }
        )

        # ExpectedGoals kaydını oluştur
        ExpectedGoals.objects.create(
            match=match,  # `match` alanını `Match` modelinden gelen kayda bağla
            home=row.get('home', 0),
            away=row.get('away', 0),
            compare_code=row.get('compareCode', 0),
            statistics_type=row.get('statisticsType', ''),
            value_type=row.get('valueType', ''),
            home_value=row.get('homeValue', 0),
            away_value=row.get('awayValue', 0),
            render_type=row.get('renderType', 0),
            key=row.get('key', ''),
            period=row.get('period', 'ALL'),
            group_name=row.get('groupName', ''),
            home_total=row.get('homeTotal', None),
            away_total=row.get('awayTotal', None)
        )
```

Bu çözümde, `Match` modelinde `match_id` yoksa yeni bir `Match` kaydı oluşturulacak, varsa mevcut kayıt kullanılacak ve `ExpectedGoals` kaydı bu `match` ile ilişkilendirilecektir.

Bu adımları uygulayarak `ExpectedGoals` modeline `match` ile ilişkili olarak verileri ekleyebilirsin. Eğer bu yöntem de hata verirse, lütfen `all_data` DataFrame'inin yapısını ve hata mesajını tekrar paylaş, daha detaylı destek verebilirim!